Workbook

Sheet WBS
B1: WBS – từ điển rút gọn
B2: Cấp 1 = 10 nhóm công việc · work package có mã HĐ A – T là hoạt động của lịch; "–" = gói quản lý dự án · cột G – I lấy từ sheet Hoạt động, lịch
B3: MÃ WBS | C3: TÊN PHẦN TỬ | D3: SẢN PHẨM | E3: PHỤ TRÁCH | F3: HĐ | G3: SỐ TUẦN | H3: TUẦN | I3: CRITICAL?
B5: 0 | C5: Atlas RMS | D5: D1 – D10; 26 tuần; 1,5 tỷ đồng | E5: Duy An (PM)
B6: 1 | C6: Quản lý dự án | D6: D8 | E6: Duy An
B7: 1.1 | C7: Khởi tạo, kế hoạch | D7: Hồ sơ khởi tạo, kế hoạch (D8) | E7: Duy An
B8: 1.1.1 | C8: Charter, kick-off | D8: Charter ký, kick-off (M0) | E8: Duy An | F8: –
B9: 1.1.2 | C9: Kế hoạch dự án | D9: Kế hoạch Sponsor duyệt (M1) | E9: Duy An | F9: –
B10: 1.1.3 | C10: Hợp đồng đối tác | D10: Hợp đồng RMS, hóa đơn, QR | E10: Lê Anh | F10: –
B11: 1.2 | C11: Giám sát, kiểm soát | D11: Hồ sơ giám sát (D8) | E11: Duy An
B12: 1.2.1 | C12: Báo cáo, EVM | D12: 13 báo cáo có SPI, CPI | E12: Tuấn Anh | F12: –
B13: 1.2.2 | C13: Thay đổi, rủi ro | D13: Nhật ký thay đổi, risk register | E13: Quang Hiếu | F13: –
B14: 2 | C14: Khảo sát, phân tích yêu cầu | D14: D9 (SRS) | E14: Đức Anh
B15: 2.1 | C15: Khảo sát hiện trạng | D15: Báo cáo hiện trạng 5 nhà hàng | E15: Đức Anh | F15: A | G15: =IFERROR(INDEX('Hoạt động, lịch'!$I$5:$I$26,MATCH($F15,'Hoạt động, lịch'!$B$5:$B$26,0)),"") -> 3 | H15: =IFERROR(INDEX('Hoạt động, lịch'!$S$5:$S$26,MATCH($F15,'Hoạt động, lịch'!$B$5:$B$26,0)),"") -> Tuần 1–3 | I15: =IFERROR(INDEX('Hoạt động, lịch'!$R$5:$R$26,MATCH($F15,'Hoạt động, lịch'!$B$5:$B$26,0)),"") -> Critical
B16: 2.2 | C16: Đặc tả yêu cầu (SRS) | D16: SRS, ma trận truy vết (M1) | E16: Đức Anh | F16: B | G16: =IFERROR(INDEX('Hoạt động, lịch'!$I$5:$I$26,MATCH($F16,'Hoạt động, lịch'!$B$5:$B$26,0)),"") -> 3 | H16: =IFERROR(INDEX('Hoạt động, lịch'!$S$5:$S$26,MATCH($F16,'Hoạt động, lịch'!$B$5:$B$26,0)),"") -> Tuần 4–6 | I16: =IFERROR(INDEX('Hoạt động, lịch'!$R$5:$R$26,MATCH($F16,'Hoạt động, lịch'!$B$5:$B$26,0)),"") -> Critical
B17: 3 | C17: Thiết kế giải pháp | D17: D9 (thiết kế) | E17: Đối tác RMS
B18: 3.1 | C18: Quy trình, cấu hình | D18: Thiết kế to-be được duyệt (M2) | E18: Đối tác RMS | F18: C | G18: =IFERROR(INDEX('Hoạt động, lịch'!$I$5:$I$26,MATCH($F18,'Hoạt động, lịch'!$B$5:$B$26,0)),"") -> 2 | H18: =IFERROR(INDEX('Hoạt động, lịch'!$S$5:$S$26,MATCH($F18,'Hoạt động, lịch'!$B$5:$B$26,0)),"") -> Tuần 7–8 | I18: =IFERROR(INDEX('Hoạt động, lịch'!$R$5:$R$26,MATCH($F18,'Hoạt động, lịch'!$B$5:$B$26,0)),"") -> Critical
B19: 3.2 | C19: Kiến trúc tích hợp | D19: Đặc tả 5 kết nối, web, QR (M2) | E19: Đối tác RMS | F19: D | G19: =IFERROR(INDEX('Hoạt động, lịch'!$I$5:$I$26,MATCH($F19,'Hoạt động, lịch'!$B$5:$B$26,0)),"") -> 2 | H19: =IFERROR(INDEX('Hoạt động, lịch'!$S$5:$S$26,MATCH($F19,'Hoạt động, lịch'!$B$5:$B$26,0)),"") -> Tuần 7–8 | I19: =IFERROR(INDEX('Hoạt động, lịch'!$R$5:$R$26,MATCH($F19,'Hoạt động, lịch'!$B$5:$B$26,0)),"")
B20: 4 | C20: Cấu hình, tích hợp | D20: D1, D2, D3 | E20: Đối tác RMS
B21: 4.1 | C21: RMS lõi | D21: P1 – P5, P7, P8 đạt demo | E21: Đối tác RMS | F21: E | G21: =IFERROR(INDEX('Hoạt động, lịch'!$I$5:$I$26,MATCH($F21,'Hoạt động, lịch'!$B$5:$B$26,0)),"") -> 6 | H21: =IFERROR(INDEX('Hoạt động, lịch'!$S$5:$S$26,MATCH($F21,'Hoạt động, lịch'!$B$5:$B$26,0)),"") -> Tuần 9–14 | I21: =IFERROR(INDEX('Hoạt động, lịch'!$R$5:$R$26,MATCH($F21,'Hoạt động, lịch'!$B$5:$B$26,0)),"") -> Critical
B22: 4.2 | C22: Tích hợp, kênh online | D22: D2, D3 trên môi trường thử | E22: Đối tác RMS
B23: 4.2.1 | C23: Tích hợp ngoài (P9) | D23: 5 kết nối ngoài chạy thử đạt | E23: Đối tác RMS | F23: F | G23: =IFERROR(INDEX('Hoạt động, lịch'!$I$5:$I$26,MATCH($F23,'Hoạt động, lịch'!$B$5:$B$26,0)),"") -> 5 | H23: =IFERROR(INDEX('Hoạt động, lịch'!$S$5:$S$26,MATCH($F23,'Hoạt động, lịch'!$B$5:$B$26,0)),"") -> Tuần 9–13 | I23: =IFERROR(INDEX('Hoạt động, lịch'!$R$5:$R$26,MATCH($F23,'Hoạt động, lịch'!$B$5:$B$26,0)),"")
B24: 4.2.2 | C24: Kênh online (P6) | D24: Web, QR order chạy thử đạt | E24: Đối tác RMS | F24: G | G24: =IFERROR(INDEX('Hoạt động, lịch'!$I$5:$I$26,MATCH($F24,'Hoạt động, lịch'!$B$5:$B$26,0)),"") -> 4 | H24: =IFERROR(INDEX('Hoạt động, lịch'!$S$5:$S$26,MATCH($F24,'Hoạt động, lịch'!$B$5:$B$26,0)),"") -> Tuần 9–12 | I24: =IFERROR(INDEX('Hoạt động, lịch'!$R$5:$R$26,MATCH($F24,'Hoạt động, lịch'!$B$5:$B$26,0)),"")
B25: 5 | C25: Thiết bị, mạng | D25: D4 | E25: Lê Anh
B26: 5.1 | C26: Thiết bị đợt 1 (pilot) | D26: Bàn giao Cầu Giấy, văn phòng | E26: Lê Anh | F26: H | G26: =IFERROR(INDEX('Hoạt động, lịch'!$I$5:$I$26,MATCH($F26,'Hoạt động, lịch'!$B$5:$B$26,0)),"") -> 4 | H26: =IFERROR(INDEX('Hoạt động, lịch'!$S$5:$S$26,MATCH($F26,'Hoạt động, lịch'!$B$5:$B$26,0)),"") -> Tuần 9–12 | I26: =IFERROR(INDEX('Hoạt động, lịch'!$R$5:$R$26,MATCH($F26,'Hoạt động, lịch'!$B$5:$B$26,0)),"")
B27: 5.2 | C27: Thiết bị đợt 2 | D27: 4 nhà hàng, lắp trước go-live | E27: Lê Anh | F27: I | G27: =IFERROR(INDEX('Hoạt động, lịch'!$I$5:$I$26,MATCH($F27,'Hoạt động, lịch'!$B$5:$B$26,0)),"") -> 5 | H27: =IFERROR(INDEX('Hoạt động, lịch'!$S$5:$S$26,MATCH($F27,'Hoạt động, lịch'!$B$5:$B$26,0)),"") -> Tuần 13–17 | I27: =IFERROR(INDEX('Hoạt động, lịch'!$R$5:$R$26,MATCH($F27,'Hoạt động, lịch'!$B$5:$B$26,0)),"")
B28: 6 | C28: Chuyển đổi dữ liệu | D28: D5 | E28: Đức Anh
B29: 6.1 | C29: Thực đơn, công thức | D29: 100% món có giá, công thức | E29: Đức Anh | F29: J | G29: =IFERROR(INDEX('Hoạt động, lịch'!$I$5:$I$26,MATCH($F29,'Hoạt động, lịch'!$B$5:$B$26,0)),"") -> 4 | H29: =IFERROR(INDEX('Hoạt động, lịch'!$S$5:$S$26,MATCH($F29,'Hoạt động, lịch'!$B$5:$B$26,0)),"") -> Tuần 9–12 | I29: =IFERROR(INDEX('Hoạt động, lịch'!$R$5:$R$26,MATCH($F29,'Hoạt động, lịch'!$B$5:$B$26,0)),"")
B30: 6.2 | C30: Khách hàng, tồn kho | D30: Tồn kho khớp 100% kiểm kê | E30: Quang Hiếu | F30: K | G30: =IFERROR(INDEX('Hoạt động, lịch'!$I$5:$I$26,MATCH($F30,'Hoạt động, lịch'!$B$5:$B$26,0)),"") -> 3 | H30: =IFERROR(INDEX('Hoạt động, lịch'!$S$5:$S$26,MATCH($F30,'Hoạt động, lịch'!$B$5:$B$26,0)),"") -> Tuần 13–15 | I30: =IFERROR(INDEX('Hoạt động, lịch'!$R$5:$R$26,MATCH($F30,'Hoạt động, lịch'!$B$5:$B$26,0)),"")
B31: 7 | C31: Kiểm thử | D31: D9 (kiểm thử) | E31: Quang Hiếu
B32: 7.1 | C32: SIT, kiểm thử tải | D32: SIT đạt; tải 300 order/giờ (M3) | E32: Đối tác RMS | F32: L | G32: =IFERROR(INDEX('Hoạt động, lịch'!$I$5:$I$26,MATCH($F32,'Hoạt động, lịch'!$B$5:$B$26,0)),"") -> 1 | H32: =IFERROR(INDEX('Hoạt động, lịch'!$S$5:$S$26,MATCH($F32,'Hoạt động, lịch'!$B$5:$B$26,0)),"") -> Tuần 15 | I32: =IFERROR(INDEX('Hoạt động, lịch'!$R$5:$R$26,MATCH($F32,'Hoạt động, lịch'!$B$5:$B$26,0)),"") -> Critical
B33: 7.2 | C33: UAT | D33: ≥ 95% test case UAT đạt (M4) | E33: Quang Hiếu | F33: M | G33: =IFERROR(INDEX('Hoạt động, lịch'!$I$5:$I$26,MATCH($F33,'Hoạt động, lịch'!$B$5:$B$26,0)),"") -> 1 | H33: =IFERROR(INDEX('Hoạt động, lịch'!$S$5:$S$26,MATCH($F33,'Hoạt động, lịch'!$B$5:$B$26,0)),"") -> Tuần 16 | I33: =IFERROR(INDEX('Hoạt động, lịch'!$R$5:$R$26,MATCH($F33,'Hoạt động, lịch'!$B$5:$B$26,0)),"") -> Critical
B34: 8 | C34: Đào tạo, tài liệu | D34: D6 | E34: Đối tác RMS
B35: 8.1 | C35: Tài liệu, trainer | D35: Tài liệu 6 vai trò; trainer đạt | E35: Đối tác RMS | F35: N | G35: =IFERROR(INDEX('Hoạt động, lịch'!$I$5:$I$26,MATCH($F35,'Hoạt động, lịch'!$B$5:$B$26,0)),"") -> 3 | H35: =IFERROR(INDEX('Hoạt động, lịch'!$S$5:$S$26,MATCH($F35,'Hoạt động, lịch'!$B$5:$B$26,0)),"") -> Tuần 12–14 | I35: =IFERROR(INDEX('Hoạt động, lịch'!$R$5:$R$26,MATCH($F35,'Hoạt động, lịch'!$B$5:$B$26,0)),"")
B36: 8.2 | C36: Đào tạo theo đợt | D36: ≥ 95% đạt, trước mỗi go-live | E36: Tuấn Anh | F36: O | G36: =IFERROR(INDEX('Hoạt động, lịch'!$I$5:$I$26,MATCH($F36,'Hoạt động, lịch'!$B$5:$B$26,0)),"") -> 6 | H36: =IFERROR(INDEX('Hoạt động, lịch'!$S$5:$S$26,MATCH($F36,'Hoạt động, lịch'!$B$5:$B$26,0)),"") -> Tuần 15–20 | I36: =IFERROR(INDEX('Hoạt động, lịch'!$R$5:$R$26,MATCH($F36,'Hoạt động, lịch'!$B$5:$B$26,0)),"")
B37: 9 | C37: Triển khai | D37: D7 | E37: Tuấn Anh
B38: 9.1 | C38: Go-live 5 nhà hàng | D38: 5/5 nhà hàng go-live | E38: Tuấn Anh
B39: 9.1.1 | C39: Pilot Cầu Giấy | D39: Go-live (M5); nghiệm thu pilot | E39: Tuấn Anh | F39: P | G39: =IFERROR(INDEX('Hoạt động, lịch'!$I$5:$I$26,MATCH($F39,'Hoạt động, lịch'!$B$5:$B$26,0)),"") -> 2 | H39: =IFERROR(INDEX('Hoạt động, lịch'!$S$5:$S$26,MATCH($F39,'Hoạt động, lịch'!$B$5:$B$26,0)),"") -> Tuần 17–18 | I39: =IFERROR(INDEX('Hoạt động, lịch'!$R$5:$R$26,MATCH($F39,'Hoạt động, lịch'!$B$5:$B$26,0)),"") -> Critical
B40: 9.1.2 | C40: Rollout 4 nhà hàng | D40: 4 nhà hàng, mỗi tuần 1 (M6) | E40: Tuấn Anh | F40: Q | G40: =IFERROR(INDEX('Hoạt động, lịch'!$I$5:$I$26,MATCH($F40,'Hoạt động, lịch'!$B$5:$B$26,0)),"") -> 4 | H40: =IFERROR(INDEX('Hoạt động, lịch'!$S$5:$S$26,MATCH($F40,'Hoạt động, lịch'!$B$5:$B$26,0)),"") -> Tuần 19–22 | I40: =IFERROR(INDEX('Hoạt động, lịch'!$R$5:$R$26,MATCH($F40,'Hoạt động, lịch'!$B$5:$B$26,0)),"") -> Critical
B41: 9.2 | C41: Hỗ trợ sau go-live | D41: Nhật ký sự cố; uptime ≥ 99,5% | E41: Đối tác RMS | F41: R | G41: =IFERROR(INDEX('Hoạt động, lịch'!$I$5:$I$26,MATCH($F41,'Hoạt động, lịch'!$B$5:$B$26,0)),"") -> 3 | H41: =IFERROR(INDEX('Hoạt động, lịch'!$S$5:$S$26,MATCH($F41,'Hoạt động, lịch'!$B$5:$B$26,0)),"") -> Tuần 23–25 | I41: =IFERROR(INDEX('Hoạt động, lịch'!$R$5:$R$26,MATCH($F41,'Hoạt động, lịch'!$B$5:$B$26,0)),"") -> Critical
...

Sheet Hoạt động, lịch
B1: Hoạt động và lịch – CPM, PERT
B2: ES(Start) = 0 = đầu tuần 1 · FS: ES ≥ EF(trước) + lag · SS: ES ≥ ES(trước) + lag · FF: EF ≥ EF(trước) + lag · Total Slack = LS − ES · PERT: t = (o + 4m + p)/6, σ² = ((p − o)/6)²
B3: ID | C3: HOẠT ĐỘNG | D3: WBS | E3: PREDECESSOR (QUAN HỆ) | F3: o | G3: m | H3: p | I3: t (TUẦN) | J3: σ² | K3: PHỤ TRÁCH | L3: ES | M3: EF | N3: LS | O3: LF | P3: TOTAL SLACK | Q3: FREE SLACK | R3: CRITICAL? | S3: TUẦN | T3: BẮT ĐẦU | U3: KẾT THÚC
B5: Start | C5: Bắt đầu dự án (M0) | D5: — | E5: — | I5: 0 | J5: =IF(COUNT(F5:H5)=3,((H5-F5)/6)^2,0) -> 0 | K5: — | L5: =0 -> 0 | M5: =L5+I5 -> 0 | N5: =O5-I5 -> 0 | O5: =MIN($D$29,N6) -> 0 | P5: =N5-L5 -> 0 | Q5: =MIN($D$29-M5,L6-M5) -> 0 | R5: =IF(ABS(P5)<0.0001,"Critical","") -> Critical | S5: =IF(I5=0,IF(L5=0,"Đầu tuần 1","Cuối tuần "&M5),"Tuần "&(L5+1)&IF(I5>1,"–"&M5,"")) -> Đầu tuần 1 | T5: =IF(AND(I5=0,L5>0),U5,$D$28+L5*7) -> 46447 | U5: =IF(I5=0,IF(M5=0,$D$28,$D$28+(M5-1)*7+4),$D$28+(M5-1)*7+4) -> 46447
B6: A | C6: Khảo sát hiện trạng | D6: 2.1 | E6: Start | I6: 3 | J6: =IF(COUNT(F6:H6)=3,((H6-F6)/6)^2,0) -> 0 | K6: Đức Anh | L6: =MAX(0,M5) -> 0 | M6: =L6+I6 -> 3 | N6: =O6-I6 -> 0 | O6: =MIN($D$29,N7) -> 3 | P6: =N6-L6 -> 0 | Q6: =MIN($D$29-M6,L7-M6) -> 0 | R6: =IF(ABS(P6)<0.0001,"Critical","") -> Critical | S6: =IF(I6=0,IF(L6=0,"Đầu tuần 1","Cuối tuần "&M6),"Tuần "&(L6+1)&IF(I6>1,"–"&M6,"")) -> Tuần 1–3 | T6: =IF(AND(I6=0,L6>0),U6,$D$28+L6*7) -> 46447 | U6: =IF(I6=0,IF(M6=0,$D$28,$D$28+(M6-1)*7+4),$D$28+(M6-1)*7+4) -> 46465
B7: B | C7: Đặc tả yêu cầu (SRS) | D7: 2.2 | E7: A | I7: 3 | J7: =IF(COUNT(F7:H7)=3,((H7-F7)/6)^2,0) -> 0 | K7: Đức Anh | L7: =MAX(0,M6) -> 3 | M7: =L7+I7 -> 6 | N7: =O7-I7 -> 3 | O7: =MIN($D$29,N8,N9) -> 6 | P7: =N7-L7 -> 0 | Q7: =MIN($D$29-M7,L8-M7,L9-M7) -> 0 | R7: =IF(ABS(P7)<0.0001,"Critical","") -> Critical | S7: =IF(I7=0,IF(L7=0,"Đầu tuần 1","Cuối tuần "&M7),"Tuần "&(L7+1)&IF(I7>1,"–"&M7,"")) -> Tuần 4–6 | T7: =IF(AND(I7=0,L7>0),U7,$D$28+L7*7) -> 46468 | U7: =IF(I7=0,IF(M7=0,$D$28,$D$28+(M7-1)*7+4),$D$28+(M7-1)*7+4) -> 46486
B8: C | C8: Quy trình to-be, thiết kế cấu hình | D8: 3.1 | E8: B | I8: 2 | J8: =IF(COUNT(F8:H8)=3,((H8-F8)/6)^2,0) -> 0 | K8: Đối tác RMS | L8: =MAX(0,M7) -> 6 | M8: =L8+I8 -> 8 | N8: =O8-I8 -> 6 | O8: =MIN($D$29,N10,N13,N15) -> 8 | P8: =N8-L8 -> 0 | Q8: =MIN($D$29-M8,L10-M8,L13-M8,L15-M8) -> 0 | R8: =IF(ABS(P8)<0.0001,"Critical","") -> Critical | S8: =IF(I8=0,IF(L8=0,"Đầu tuần 1","Cuối tuần "&M8),"Tuần "&(L8+1)&IF(I8>1,"–"&M8,"")) -> Tuần 7–8 | T8: =IF(AND(I8=0,L8>0),U8,$D$28+L8*7) -> 46489 | U8: =IF(I8=0,IF(M8=0,$D$28,$D$28+(M8-1)*7+4),$D$28+(M8-1)*7+4) -> 46500
B9: D | C9: Kiến trúc tích hợp | D9: 3.2 | E9: B | I9: 2 | J9: =IF(COUNT(F9:H9)=3,((H9-F9)/6)^2,0) -> 0 | K9: Đối tác RMS | L9: =MAX(0,M7) -> 6 | M9: =L9+I9 -> 8 | N9: =O9-I9 -> 7 | O9: =MIN($D$29,N11,N12) -> 9 | P9: =N9-L9 -> 1 | Q9: =MIN($D$29-M9,L11-M9,L12-M9) -> 0 | R9: =IF(ABS(P9)<0.0001,"Critical","") | S9: =IF(I9=0,IF(L9=0,"Đầu tuần 1","Cuối tuần "&M9),"Tuần "&(L9+1)&IF(I9>1,"–"&M9,"")) -> Tuần 7–8 | T9: =IF(AND(I9=0,L9>0),U9,$D$28+L9*7) -> 46489 | U9: =IF(I9=0,IF(M9=0,$D$28,$D$28+(M9-1)*7+4),$D$28+(M9-1)*7+4) -> 46500
B10: E | C10: Cấu hình RMS lõi | D10: 4.1 | E10: C | F10: 4 | G10: 6 | H10: 8 | I10: =(F10+4*G10+H10)/6 -> 6 | J10: =IF(COUNT(F10:H10)=3,((H10-F10)/6)^2,0) -> 0.44444444 | K10: Đối tác RMS | L10: =MAX(0,M8) -> 8 | M10: =L10+I10 -> 14 | N10: =O10-I10 -> 8 | O10: =MIN($D$29,N17,N19-3+I10) -> 14 | P10: =N10-L10 -> 0 | Q10: =MIN($D$29-M10,L17-M10,L19-3-L10) -> 0 | R10: =IF(ABS(P10)<0.0001,"Critical","") -> Critical | S10: =IF(I10=0,IF(L10=0,"Đầu tuần 1","Cuối tuần "&M10),"Tuần "&(L10+1)&IF(I10>1,"–"&M10,"")) -> Tuần 9–14 | T10: =IF(AND(I10=0,L10>0),U10,$D$28+L10*7) -> 46503 | U10: =IF(I10=0,IF(M10=0,$D$28,$D$28+(M10-1)*7+4),$D$28+(M10-1)*7+4) -> 46542
B11: F | C11: Tích hợp ngoài (P9) | D11: 4.2.1 | E11: D | F11: 3 | G11: 4 | H11: 11 | I11: =(F11+4*G11+H11)/6 -> 5 | J11: =IF(COUNT(F11:H11)=3,((H11-F11)/6)^2,0) -> 1.7777778 | K11: Đối tác RMS | L11: =MAX(0,M9) -> 8 | M11: =L11+I11 -> 13 | N11: =O11-I11 -> 9 | O11: =MIN($D$29,N17) -> 14 | P11: =N11-L11 -> 1 | Q11: =MIN($D$29-M11,L17-M11) -> 1 | R11: =IF(ABS(P11)<0.0001,"Critical","") | S11: =IF(I11=0,IF(L11=0,"Đầu tuần 1","Cuối tuần "&M11),"Tuần "&(L11+1)&IF(I11>1,"–"&M11,"")) -> Tuần 9–13 | T11: =IF(AND(I11=0,L11>0),U11,$D$28+L11*7) -> 46503 | U11: =IF(I11=0,IF(M11=0,$D$28,$D$28+(M11-1)*7+4),$D$28+(M11-1)*7+4) -> 46535
B12: G | C12: Kênh online (P6) | D12: 4.2.2 | E12: D | I12: 4 | J12: =IF(COUNT(F12:H12)=3,((H12-F12)/6)^2,0) -> 0 | K12: Đối tác RMS | L12: =MAX(0,M9) -> 8 | M12: =L12+I12 -> 12 | N12: =O12-I12 -> 10 | O12: =MIN($D$29,N17) -> 14 | P12: =N12-L12 -> 2 | Q12: =MIN($D$29-M12,L17-M12) -> 2 | R12: =IF(ABS(P12)<0.0001,"Critical","") | S12: =IF(I12=0,IF(L12=0,"Đầu tuần 1","Cuối tuần "&M12),"Tuần "&(L12+1)&IF(I12>1,"–"&M12,"")) -> Tuần 9–12 | T12: =IF(AND(I12=0,L12>0),U12,$D$28+L12*7) -> 46503 | U12: =IF(I12=0,IF(M12=0,$D$28,$D$28+(M12-1)*7+4),$D$28+(M12-1)*7+4) -> 46528
B13: H | C13: Thiết bị đợt 1 (pilot) | D13: 5.1 | E13: C | I13: 4 | J13: =IF(COUNT(F13:H13)=3,((H13-F13)/6)^2,0) -> 0 | K13: Lê Anh | L13: =MAX(0,M8) -> 8 | M13: =L13+I13 -> 12 | N13: =O13-I13 -> 9 | O13: =MIN($D$29,N14,N17) -> 13 | P13: =N13-L13 -> 1 | Q13: =MIN($D$29-M13,L14-M13,L17-M13) -> 0 | R13: =IF(ABS(P13)<0.0001,"Critical","") | S13: =IF(I13=0,IF(L13=0,"Đầu tuần 1","Cuối tuần "&M13),"Tuần "&(L13+1)&IF(I13>1,"–"&M13,"")) -> Tuần 9–12 | T13: =IF(AND(I13=0,L13>0),U13,$D$28+L13*7) -> 46503 | U13: =IF(I13=0,IF(M13=0,$D$28,$D$28+(M13-1)*7+4),$D$28+(M13-1)*7+4) -> 46528
B14: I | C14: Thiết bị đợt 2 | D14: 5.2 | E14: H | F14: 4 | G14: 4 | H14: 10 | I14: =(F14+4*G14+H14)/6 -> 5 | J14: =IF(COUNT(F14:H14)=3,((H14-F14)/6)^2,0) -> 1 | K14: Lê Anh | L14: =MAX(0,M13) -> 12 | M14: =L14+I14 -> 17 | N14: =O14-I14 -> 13 | O14: =MIN($D$29,N22) -> 18 | P14: =N14-L14 -> 1 | Q14: =MIN($D$29-M14,L22-M14) -> 1 | R14: =IF(ABS(P14)<0.0001,"Critical","") | S14: =IF(I14=0,IF(L14=0,"Đầu tuần 1","Cuối tuần "&M14),"Tuần "&(L14+1)&IF(I14>1,"–"&M14,"")) -> Tuần 13–17 | T14: =IF(AND(I14=0,L14>0),U14,$D$28+L14*7) -> 46531 | U14: =IF(I14=0,IF(M14=0,$D$28,$D$28+(M14-1)*7+4),$D$28+(M14-1)*7+4) -> 46563
B15: J | C15: Thực đơn, công thức | D15: 6.1 | E15: C | I15: 4 | J15: =IF(COUNT(F15:H15)=3,((H15-F15)/6)^2,0) -> 0 | K15: Đức Anh | L15: =MAX(0,M8) -> 8 | M15: =L15+I15 -> 12 | N15: =O15-I15 -> 9 | O15: =MIN($D$29,N16,N17) -> 13 | P15: =N15-L15 -> 1 | Q15: =MIN($D$29-M15,L16-M15,L17-M15) -> 0 | R15: =IF(ABS(P15)<0.0001,"Critical","") | S15: =IF(I15=0,IF(L15=0,"Đầu tuần 1","Cuối tuần "&M15),"Tuần "&(L15+1)&IF(I15>1,"–"&M15,"")) -> Tuần 9–12 | T15: =IF(AND(I15=0,L15>0),U15,$D$28+L15*7) -> 46503 | U15: =IF(I15=0,IF(M15=0,$D$28,$D$28+(M15-1)*7+4),$D$28+(M15-1)*7+4) -> 46528
B16: K | C16: Khách hàng, tồn kho đầu kỳ | D16: 6.2 | E16: J | I16: 3 | J16: =IF(COUNT(F16:H16)=3,((H16-F16)/6)^2,0) -> 0 | K16: Quang Hiếu | L16: =MAX(0,M15) -> 12 | M16: =L16+I16 -> 15 | N16: =O16-I16 -> 13 | O16: =MIN($D$29,N21) -> 16 | P16: =N16-L16 -> 1 | Q16: =MIN($D$29-M16,L21-M16) -> 1 | R16: =IF(ABS(P16)<0.0001,"Critical","") | S16: =IF(I16=0,IF(L16=0,"Đầu tuần 1","Cuối tuần "&M16),"Tuần "&(L16+1)&IF(I16>1,"–"&M16,"")) -> Tuần 13–15 | T16: =IF(AND(I16=0,L16>0),U16,$D$28+L16*7) -> 46531 | U16: =IF(I16=0,IF(M16=0,$D$28,$D$28+(M16-1)*7+4),$D$28+(M16-1)*7+4) -> 46549
B17: L | C17: SIT, kiểm thử tải | D17: 7.1 | E17: E; F; G; H; J | I17: 1 | J17: =IF(COUNT(F17:H17)=3,((H17-F17)/6)^2,0) -> 0 | K17: Đối tác RMS | L17: =MAX(0,M10,M11,M12,M13,M15) -> 14 | M17: =L17+I17 -> 15 | N17: =O17-I17 -> 14 | O17: =MIN($D$29,N18) -> 15 | P17: =N17-L17 -> 0 | Q17: =MIN($D$29-M17,L18-M17) -> 0 | R17: =IF(ABS(P17)<0.0001,"Critical","") -> Critical | S17: =IF(I17=0,IF(L17=0,"Đầu tuần 1","Cuối tuần "&M17),"Tuần "&(L17+1)&IF(I17>1,"–"&M17,"")) -> Tuần 15 | T17: =IF(AND(I17=0,L17>0),U17,$D$28+L17*7) -> 46545 | U17: =IF(I17=0,IF(M17=0,$D$28,$D$28+(M17-1)*7+4),$D$28+(M17-1)*7+4) -> 46549
B18: M | C18: UAT | D18: 7.2 | E18: L | I18: 1 | J18: =IF(COUNT(F18:H18)=3,((H18-F18)/6)^2,0) -> 0 | K18: Quang Hiếu | L18: =MAX(0,M17) -> 15 | M18: =L18+I18 -> 16 | N18: =O18-I18 -> 15 | O18: =MIN($D$29,N21) -> 16 | P18: =N18-L18 -> 0 | Q18: =MIN($D$29-M18,L21-M18) -> 0 | R18: =IF(ABS(P18)<0.0001,"Critical","") -> Critical | S18: =IF(I18=0,IF(L18=0,"Đầu tuần 1","Cuối tuần "&M18),"Tuần "&(L18+1)&IF(I18>1,"–"&M18,"")) -> Tuần 16 | T18: =IF(AND(I18=0,L18>0),U18,$D$28+L18*7) -> 46552 | U18: =IF(I18=0,IF(M18=0,$D$28,$D$28+(M18-1)*7+4),$D$28+(M18-1)*7+4) -> 46556
B19: N | C19: Tài liệu, đào tạo trainer | D19: 8.1 | E19: E (SS+3) | I19: 3 | J19: =IF(COUNT(F19:H19)=3,((H19-F19)/6)^2,0) -> 0 | K19: Đối tác RMS | L19: =MAX(0,L10+3) -> 11 | M19: =L19+I19 -> 14 | N19: =O19-I19 -> 12 | O19: =MIN($D$29,N20) -> 15 | P19: =N19-L19 -> 1 | Q19: =MIN($D$29-M19,L20-M19) -> 0 | R19: =IF(ABS(P19)<0.0001,"Critical","") | S19: =IF(I19=0,IF(L19=0,"Đầu tuần 1","Cuối tuần "&M19),"Tuần "&(L19+1)&IF(I19>1,"–"&M19,"")) -> Tuần 12–14 | T19: =IF(AND(I19=0,L19>0),U19,$D$28+L19*7) -> 46524 | U19: =IF(I19=0,IF(M19=0,$D$28,$D$28+(M19-1)*7+4),$D$28+(M19-1)*7+4) -> 46542
B20: O | C20: Đào tạo nhân viên theo đợt | D20: 8.2 | E20: N | I20: 6 | J20: =IF(COUNT(F20:H20)=3,((H20-F20)/6)^2,0) -> 0 | K20: Tuấn Anh | L20: =MAX(0,M19) -> 14 | M20: =L20+I20 -> 20 | N20: =O20-I20 -> 15 | O20: =MIN($D$29,N21-1+I20,O22-1) -> 21 | P20: =N20-L20 -> 1 | Q20: =MIN($D$29-M20,L21-1-L20,M22-1-M20) -> 1 | R20: =IF(ABS(P20)<0.0001,"Critical","") | S20: =IF(I20=0,IF(L20=0,"Đầu tuần 1","Cuối tuần "&M20),"Tuần "&(L20+1)&IF(I20>1,"–"&M20,"")) -> Tuần 15–20 | T20: =IF(AND(I20=0,L20>0),U20,$D$28+L20*7) -> 46545 | U20: =IF(I20=0,IF(M20=0,$D$28,$D$28+(M20-1)*7+4),$D$28+(M20-1)*7+4) -> 46584
B21: P | C21: Pilot Cầu Giấy | D21: 9.1.1 | E21: M; K; O (SS+1) | I21: 2 | J21: =IF(COUNT(F21:H21)=3,((H21-F21)/6)^2,0) -> 0 | K21: Tuấn Anh | L21: =MAX(0,M18,M16,L20+1) -> 16 | M21: =L21+I21 -> 18 | N21: =O21-I21 -> 16 | O21: =MIN($D$29,N22) -> 18 | P21: =N21-L21 -> 0 | Q21: =MIN($D$29-M21,L22-M21) -> 0 | R21: =IF(ABS(P21)<0.0001,"Critical","") -> Critical | S21: =IF(I21=0,IF(L21=0,"Đầu tuần 1","Cuối tuần "&M21),"Tuần "&(L21+1)&IF(I21>1,"–"&M21,"")) -> Tuần 17–18 | T21: =IF(AND(I21=0,L21>0),U21,$D$28+L21*7) -> 46559 | U21: =IF(I21=0,IF(M21=0,$D$28,$D$28+(M21-1)*7+4),$D$28+(M21-1)*7+4) -> 46570
B22: Q | C22: Rollout 4 nhà hàng | D22: 9.1.2 | E22: P; I; O (FF+1) | I22: 4 | J22: =IF(COUNT(F22:H22)=3,((H22-F22)/6)^2,0) -> 0 | K22: Tuấn Anh | L22: =MAX(0,M21,M14,M20+1-I22) -> 18 | M22: =L22+I22 -> 22 | N22: =O22-I22 -> 18 | O22: =MIN($D$29,N23) -> 22 | P22: =N22-L22 -> 0 | Q22: =MIN($D$29-M22,L23-M22) -> 0 | R22: =IF(ABS(P22)<0.0001,"Critical","") -> Critical | S22: =IF(I22=0,IF(L22=0,"Đầu tuần 1","Cuối tuần "&M22),"Tuần "&(L22+1)&IF(I22>1,"–"&M22,"")) -> Tuần 19–22 | T22: =IF(AND(I22=0,L22>0),U22,$D$28+L22*7) -> 46573 | U22: =IF(I22=0,IF(M22=0,$D$28,$D$28+(M22-1)*7+4),$D$28+(M22-1)*7+4) -> 46598
B23: R | C23: Hỗ trợ sau go-live | D23: 9.2 | E23: Q | I23: 3 | J23: =IF(COUNT(F23:H23)=3,((H23-F23)/6)^2,0) -> 0 | K23: Đối tác RMS | L23: =MAX(0,M22) -> 22 | M23: =L23+I23 -> 25 | N23: =O23-I23 -> 22 | O23: =MIN($D$29,N24,N25) -> 25 | P23: =N23-L23 -> 0 | Q23: =MIN($D$29-M23,L24-M23,L25-M23) -> 0 | R23: =IF(ABS(P23)<0.0001,"Critical","") -> Critical | S23: =IF(I23=0,IF(L23=0,"Đầu tuần 1","Cuối tuần "&M23),"Tuần "&(L23+1)&IF(I23>1,"–"&M23,"")) -> Tuần 23–25 | T23: =IF(AND(I23=0,L23>0),U23,$D$28+L23*7) -> 46601 | U23: =IF(I23=0,IF(M23=0,$D$28,$D$28+(M23-1)*7+4),$D$28+(M23-1)*7+4) -> 46619
B24: S | C24: Nghiệm thu, bàn giao | D24: 10.1 | E24: R | I24: 1 | J24: =IF(COUNT(F24:H24)=3,((H24-F24)/6)^2,0) -> 0 | K24: Duy An | L24: =MAX(0,M23) -> 25 | M24: =L24+I24 -> 26 | N24: =O24-I24 -> 25 | O24: =MIN($D$29,N26) -> 26 | P24: =N24-L24 -> 0 | Q24: =MIN($D$29-M24,L26-M24) -> 0 | R24: =IF(ABS(P24)<0.0001,"Critical","") -> Critical | S24: =IF(I24=0,IF(L24=0,"Đầu tuần 1","Cuối tuần "&M24),"Tuần "&(L24+1)&IF(I24>1,"–"&M24,"")) -> Tuần 26 | T24: =IF(AND(I24=0,L24>0),U24,$D$28+L24*7) -> 46622 | U24: =IF(I24=0,IF(M24=0,$D$28,$D$28+(M24-1)*7+4),$D$28+(M24-1)*7+4) -> 46626
B25: T | C25: Tổng kết, thanh lý hợp đồng | D25: 10.2 | E25: R | I25: 1 | J25: =IF(COUNT(F25:H25)=3,((H25-F25)/6)^2,0) -> 0 | K25: Lê Anh | L25: =MAX(0,M23) -> 25 | M25: =L25+I25 -> 26 | N25: =O25-I25 -> 25 | O25: =MIN($D$29,N26) -> 26 | P25: =N25-L25 -> 0 | Q25: =MIN($D$29-M25,L26-M25) -> 0 | R25: =IF(ABS(P25)<0.0001,"Critical","") -> Critical | S25: =IF(I25=0,IF(L25=0,"Đầu tuần 1","Cuối tuần "&M25),"Tuần "&(L25+1)&IF(I25>1,"–"&M25,"")) -> Tuần 26 | T25: =IF(AND(I25=0,L25>0),U25,$D$28+L25*7) -> 46622 | U25: =IF(I25=0,IF(M25=0,$D$28,$D$28+(M25-1)*7+4),$D$28+(M25-1)*7+4) -> 46626
B26: End | C26: Kết thúc dự án (M7) | D26: — | E26: S; T | I26: 0 | J26: =IF(COUNT(F26:H26)=3,((H26-F26)/6)^2,0) -> 0 | K26: — | L26: =MAX(0,M24,M25) -> 26 | M26: =L26+I26 -> 26 | N26: =O26-I26 -> 26 | O26: =MIN($D$29) -> 26 | P26: =N26-L26 -> 0 | Q26: =MIN($D$29-M26) -> 0 | R26: =IF(ABS(P26)<0.0001,"Critical","") -> Critical | S26: =IF(I26=0,IF(L26=0,"Đầu tuần 1","Cuối tuần "&M26),"Tuần "&(L26+1)&IF(I26>1,"–"&M26,"")) -> Cuối tuần 26 | T26: =IF(AND(I26=0,L26>0),U26,$D$28+L26*7) -> 46626 | U26: =IF(I26=0,IF(M26=0,$D$28,$D$28+(M26-1)*7+4),$D$28+(M26-1)*7+4) -> 46626
B28: Ngày bắt đầu dự án (thứ Hai, tuần 1) | D28: 46447
B29: Thời gian dự án (tuần) = max EF | D29: =MAX(M5:M26) -> 26
B30: σ² trên Critical Path = Σ σ² việc găng | D30: =SUMPRODUCT((ABS(P5:P26)<0.0001)*J5:J26) -> 0.44444444
B31: σ Critical Path | D31: =SQRT(D30) -> 0.66666667
B32: Hạn hoàn thành theo Charter (tuần) | D32: 26
B33: P(T ≤ hạn) = Φ((hạn − T)/σ) | D33: =_xlfn.NORM.S.DIST(($D$32-$D$29)/D31,TRUE) -> 0.5
B34: Critical activities (Total Slack = 0) | D34: {=_xlfn.TEXTJOIN(", ",TRUE,IF(ABS(P5:P26)<0.0001,B5:B26,""))} -> Start, A, B, C, E, L, M, P, Q, R, S, T, End
B36: Cột o, m, p, t (việc không có PERT), Predecessor, Phụ trách: dữ liệu nhập; các cột còn lại tính bằng công thức. Tuần ES+1 đến hết tuần EF; ngày kết thúc là thứ Sáu.

Sheet Gantt
B1: Atlas RMS – Gantt chart lịch dự án 26 tuần
B2: 1 cột = 1 tuần (5 ngày làm việc) · hàng trên: ngày thứ Hai của tuần · thanh cam = critical activity · nền nhạt sau thanh = Total Slack · ◆ = mốc
B3: HOẠT ĐỘNG | C3: PHỤ TRÁCH | D3: TUẦN BẮT ĐẦU | E3: SỐ TUẦN | F3: ='Hoạt động, lịch'!$D$28+(F$4-1)*7 -> 46447 | G3: ='Hoạt động, lịch'!$D$28+(G$4-1)*7 -> 46454 | H3: ='Hoạt động, lịch'!$D$28+(H$4-1)*7 -> 46461 | I3: ='Hoạt động, lịch'!$D$28+(I$4-1)*7 -> 46468 | J3: ='Hoạt động, lịch'!$D$28+(J$4-1)*7 -> 46475 | K3: ='Hoạt động, lịch'!$D$28+(K$4-1)*7 -> 46482 | L3: ='Hoạt động, lịch'!$D$28+(L$4-1)*7 -> 46489 | M3: ='Hoạt động, lịch'!$D$28+(M$4-1)*7 -> 46496 | ... AE3: ='Hoạt động, lịch'!$D$28+(AE$4-1)*7 -> 46622
F4: 1 | G4: 2 | H4: 3 | I4: 4 | J4: 5 | K4: 6 | L4: 7 | M4: 8 | N4: 9 | O4: 10 | P4: 11 | Q4: 12 | R4: 13 | S4: 14 | T4: 15 | U4: 16 | V4: 17 | W4: 18 | X4: 19 | Y4: 20 | Z4: 21 | AA4: 22 | AB4: 23 | AC4: 24 | AD4: 25 | AE4: 26
B5: ='Hoạt động, lịch'!$B6&". "&'Hoạt động, lịch'!$C6 -> A. Khảo sát hiện trạng | C5: ='Hoạt động, lịch'!$K6 -> Đức Anh | D5: ='Hoạt động, lịch'!$L6+1 -> 1 | E5: ='Hoạt động, lịch'!$I6 -> 3 | AG5: ='Hoạt động, lịch'!$P6 -> 0
B6: ='Hoạt động, lịch'!$B7&". "&'Hoạt động, lịch'!$C7 -> B. Đặc tả yêu cầu (SRS) | C6: ='Hoạt động, lịch'!$K7 -> Đức Anh | D6: ='Hoạt động, lịch'!$L7+1 -> 4 | E6: ='Hoạt động, lịch'!$I7 -> 3 | AG6: ='Hoạt động, lịch'!$P7 -> 0
B7: ='Hoạt động, lịch'!$B8&". "&'Hoạt động, lịch'!$C8 -> C. Quy trình to-be, thiết kế cấu hình | C7: ='Hoạt động, lịch'!$K8 -> Đối tác RMS | D7: ='Hoạt động, lịch'!$L8+1 -> 7 | E7: ='Hoạt động, lịch'!$I8 -> 2 | AG7: ='Hoạt động, lịch'!$P8 -> 0
B8: ='Hoạt động, lịch'!$B9&". "&'Hoạt động, lịch'!$C9 -> D. Kiến trúc tích hợp | C8: ='Hoạt động, lịch'!$K9 -> Đối tác RMS | D8: ='Hoạt động, lịch'!$L9+1 -> 7 | E8: ='Hoạt động, lịch'!$I9 -> 2 | AG8: ='Hoạt động, lịch'!$P9 -> 1
B9: ='Hoạt động, lịch'!$B10&". "&'Hoạt động, lịch'!$C10 -> E. Cấu hình RMS lõi | C9: ='Hoạt động, lịch'!$K10 -> Đối tác RMS | D9: ='Hoạt động, lịch'!$L10+1 -> 9 | E9: ='Hoạt động, lịch'!$I10 -> 6 | AG9: ='Hoạt động, lịch'!$P10 -> 0
B10: ='Hoạt động, lịch'!$B11&". "&'Hoạt động, lịch'!$C11 -> F. Tích hợp ngoài (P9) | C10: ='Hoạt động, lịch'!$K11 -> Đối tác RMS | D10: ='Hoạt động, lịch'!$L11+1 -> 9 | E10: ='Hoạt động, lịch'!$I11 -> 5 | AG10: ='Hoạt động, lịch'!$P11 -> 1
B11: ='Hoạt động, lịch'!$B12&". "&'Hoạt động, lịch'!$C12 -> G. Kênh online (P6) | C11: ='Hoạt động, lịch'!$K12 -> Đối tác RMS | D11: ='Hoạt động, lịch'!$L12+1 -> 9 | E11: ='Hoạt động, lịch'!$I12 -> 4 | AG11: ='Hoạt động, lịch'!$P12 -> 2
B12: ='Hoạt động, lịch'!$B13&". "&'Hoạt động, lịch'!$C13 -> H. Thiết bị đợt 1 (pilot) | C12: ='Hoạt động, lịch'!$K13 -> Lê Anh | D12: ='Hoạt động, lịch'!$L13+1 -> 9 | E12: ='Hoạt động, lịch'!$I13 -> 4 | AG12: ='Hoạt động, lịch'!$P13 -> 1
B13: ='Hoạt động, lịch'!$B14&". "&'Hoạt động, lịch'!$C14 -> I. Thiết bị đợt 2 | C13: ='Hoạt động, lịch'!$K14 -> Lê Anh | D13: ='Hoạt động, lịch'!$L14+1 -> 13 | E13: ='Hoạt động, lịch'!$I14 -> 5 | AG13: ='Hoạt động, lịch'!$P14 -> 1
B14: ='Hoạt động, lịch'!$B15&". "&'Hoạt động, lịch'!$C15 -> J. Thực đơn, công thức | C14: ='Hoạt động, lịch'!$K15 -> Đức Anh | D14: ='Hoạt động, lịch'!$L15+1 -> 9 | E14: ='Hoạt động, lịch'!$I15 -> 4 | AG14: ='Hoạt động, lịch'!$P15 -> 1
B15: ='Hoạt động, lịch'!$B16&". "&'Hoạt động, lịch'!$C16 -> K. Khách hàng, tồn kho đầu kỳ | C15: ='Hoạt động, lịch'!$K16 -> Quang Hiếu | D15: ='Hoạt động, lịch'!$L16+1 -> 13 | E15: ='Hoạt động, lịch'!$I16 -> 3 | AG15: ='Hoạt động, lịch'!$P16 -> 1
B16: ='Hoạt động, lịch'!$B17&". "&'Hoạt động, lịch'!$C17 -> L. SIT, kiểm thử tải | C16: ='Hoạt động, lịch'!$K17 -> Đối tác RMS | D16: ='Hoạt động, lịch'!$L17+1 -> 15 | E16: ='Hoạt động, lịch'!$I17 -> 1 | AG16: ='Hoạt động, lịch'!$P17 -> 0
... B24: ='Hoạt động, lịch'!$B25&". "&'Hoạt động, lịch'!$C25 -> T. Tổng kết, thanh lý hợp đồng | C24: ='Hoạt động, lịch'!$K25 -> Lê Anh | D24: ='Hoạt động, lịch'!$L25+1 -> 26 | E24: ='Hoạt động, lịch'!$I25 -> 1 | AG24: ='Hoạt động, lịch'!$P25 -> 0
B25: ◆ Mốc quan trọng M0 – M7 | F25: M0 | K25: M1 | M25: M2 | T25: M3 | U25: M4 | V25: M5 | AA25: M6 | AE25: M7
B26: Số hoạt động chạy song song | F26: =SUMPRODUCT((F$4>=$D$5:$D$24)*(F$4<=$D$5:$D$24+$E$5:$E$24-1)) -> 1 | G26: =SUMPRODUCT((G$4>=$D$5:$D$24)*(G$4<=$D$5:$D$24+$E$5:$E$24-1)) -> 1 | H26: =SUMPRODUCT((H$4>=$D$5:$D$24)*(H$4<=$D$5:$D$24+$E$5:$E$24-1)) -> 1 | I26: =SUMPRODUCT((I$4>=$D$5:$D$24)*(I$4<=$D$5:$D$24+$E$5:$E$24-1)) -> 1 | J26: =SUMPRODUCT((J$4>=$D$5:$D$24)*(J$4<=$D$5:$D$24+$E$5:$E$24-1)) -> 1 | K26: =SUMPRODUCT((K$4>=$D$5:$D$24)*(K$4<=$D$5:$D$24+$E$5:$E$24-1)) -> 1 | L26: =SUMPRODUCT((L$4>=$D$5:$D$24)*(L$4<=$D$5:$D$24+$E$5:$E$24-1)) -> 2 | M26: =SUMPRODUCT((M$4>=$D$5:$D$24)*(M$4<=$D$5:$D$24+$E$5:$E$24-1)) -> 2 | ... AE26: =SUMPRODUCT((AE$4>=$D$5:$D$24)*(AE$4<=$D$5:$D$24+$E$5:$E$24-1)) -> 2
B27: Chú giải: | G27: Critical activity | M27: Non-critical | S27: Total Slack | Y27: Mốc
B29: Mốc: M0 01/03 kick-off · M1 09/04 SRS duyệt · M2 23/04 thiết kế duyệt · M3 11/06 xong SIT · M4 18/06 UAT đạt · M5 21/06 go-live pilot · M6 30/07 5/5 go-live · M7 27/08 nghiệm thu
B30: ="Critical Path: Start → A → B → C → E → L → M → P → Q → R → S/T → End = "&'Hoạt động, lịch'!$D$29&" tuần · P(hoàn thành ≤ "&'Hoạt động, lịch'!$D$32&" tuần) = "&TEXT('Hoạt động, lịch'!$D$33,"0%")&" (PERT)" -> Critical Path: Start → A → B → C → E → L → M → P → Q → R → S/T → End = 26 tuần · P(hoàn thành ≤ 26 tuần) = 50% (PERT)

Sheet Nguồn lực
B1: Kế hoạch nguồn lực và đơn giá
B2: Đơn vị: triệu đồng · đơn giá kế hoạch (lương nội bộ gồm bảo hiểm, báo giá tham khảo 2026) · ngày công, thành tiền tổng hợp từ sheet Chi phí
B3: MÃ | C3: NGUỒN LỰC | D3: ĐƠN GIÁ / NGÀY CÔNG | E3: NGÀY CÔNG | F3: NGƯỜI-THÁNG (22 NGÀY) | G3: THÀNH TIỀN | H3: THAM GIA | I3: CƠ SỞ ĐƠN GIÁ
B5: TV | C5: Tư vấn triển khai đối tác RMS | D5: 2 | E5: =SUMIFS('Chi phí'!$G:$G,'Chi phí'!$F:$F,$B5,'Chi phí'!$E:$E,"Nhân sự") -> 180 | F5: =E5/22 -> 8.1818182 | G5: =D5*E5 -> 360 | H5: Tuần 7 – 26, theo gói 3.x – 10.1 | I5: Báo giá dịch vụ triển khai tham khảo ≈ 44 triệu đồng/người-tháng (22 ngày)
B6: BA | C6: BA đối tác | D6: 1.5 | E6: =SUMIFS('Chi phí'!$G:$G,'Chi phí'!$F:$F,$B6,'Chi phí'!$E:$E,"Nhân sự") -> 40 | F6: =E6/22 -> 1.8181818 | G6: =D6*E6 -> 60 | H6: Tuần 1 – 8 và 16 (UAT) | I6: ≈ 33 triệu đồng/người-tháng
B7: PM | C7: PM nội bộ | D7: 1.5 | E7: =SUMIFS('Chi phí'!$G:$G,'Chi phí'!$F:$F,$B7,'Chi phí'!$E:$E,"Nhân sự") -> 40 | F7: =E7/22 -> 1.8181818 | G7: =D7*E7 -> 60 | H7: Tuần 1 – 26, ≈ 30% thời gian | I7: Lương + bảo hiểm ≈ 33 triệu đồng/tháng
B8: NB | C8: Nhân sự nội bộ (Ban QLDA, IT, trainer, nhập liệu) | D8: 1 | E8: =SUMIFS('Chi phí'!$G:$G,'Chi phí'!$F:$F,$B8,'Chi phí'!$E:$E,"Nhân sự") -> 160 | F8: =E8/22 -> 7.2727273 | G8: =D8*E8 -> 160 | H8: Theo gói được giao | I8: Lương + bảo hiểm ≈ 22 triệu đồng/tháng
C9: Tổng nhân sự | E9: =SUM(E5:E8) -> 420 | F9: =SUM(F5:F8) -> 19.090909 | G9: =SUM(G5:G8) -> 640
B10: Key user (quản lý nhà hàng, bếp trưởng, kế toán) tham gia ≤ 20% thời gian – không tính vào chi phí dự án (chi phí vận hành). Ô tô màu: dữ liệu nhập.
B12: Bộ thiết bị cho 1 nhà hàng (báo giá tham khảo)
C13: THIẾT BỊ | D13: SỐ LƯỢNG | E13: ĐƠN GIÁ | F13: THÀNH TIỀN
C15: Máy POS cảm ứng | D15: 2 | E15: 12 | F15: =D15*E15 -> 24
C16: Máy tính bảng order | D16: 6 | E16: 4.5 | F16: =D16*E16 -> 27
C17: Màn hình bếp KDS chịu nhiệt | D17: 2 | E17: 8 | F17: =D17*E17 -> 16
C18: Máy in hóa đơn, in bếp | D18: 3 | E18: 3 | F18: =D18*E18 -> 9
C19: Bộ phát Wi-Fi | D19: 3 | E19: 2.5 | F19: =D19*E19 -> 7.5
C20: Router 4G dự phòng, switch | D20: 1 | E20: 5 | F20: =D20*E20 -> 5
C21: Đi dây mạng, UPS, lắp đặt | D21: 1 | E21: 3.5 | F21: =D21*E21 -> 3.5
C22: Tổng 1 nhà hàng | F22: =SUM(F15:F21) -> 92

Sheet Chi phí
B1: Chi phí bottom-up theo work package
B2: Đơn vị: triệu đồng · Thành tiền = Số lượng × Đơn giá · tuần lấy từ sheet Hoạt động, lịch (ES + 1 đến EF) · T3 – T8: phân bổ đều theo tuần
B3: WBS | C3: HĐ | D3: NỘI DUNG | E3: LOẠI CHI PHÍ | F3: NGUỒN LỰC | G3: SỐ LƯỢNG | H3: ĐƠN VỊ | I3: ĐƠN GIÁ | J3: THÀNH TIỀN | K3: TUẦN TỪ | L3: TUẦN ĐẾN | M3: PHÂN BỔ THEO THÁNG (cost baseline)
M4: 3 | N4: 4 | O4: 5 | P4: 6 | Q4: 7 | R4: 8
B5: 1.1.1 | C5: =IFERROR(INDEX(WBS!$F$5:$F$44,MATCH($B5,WBS!$B$5:$B$44,0)),"") -> – | D5: PM lập Charter, kick-off | E5: Nhân sự | F5: PM | G5: 2 | H5: ngày công | I5: =INDEX('Nguồn lực'!$D$5:$D$8,MATCH($F5,'Nguồn lực'!$B$5:$B$8,0)) -> 1.5 | J5: =G5*I5 -> 3 | K5: 1 | L5: 1 | M5: =IF($J5=0,0,$J5*SUMPRODUCT(('Cost baseline'!$C$4:$AB$4>=$K5)*('Cost baseline'!$C$4:$AB$4<=$L5)*('Cost baseline'!$C$5:$AB$5=M$4))/($L5-$K5+1)) -> 3 | N5: =IF($J5=0,0,$J5*SUMPRODUCT(('Cost baseline'!$C$4:$AB$4>=$K5)*('Cost baseline'!$C$4:$AB$4<=$L5)*('Cost baseline'!$C$5:$AB$5=N$4))/($L5-$K5+1)) -> 0 | O5: =IF($J5=0,0,$J5*SUMPRODUCT(('Cost baseline'!$C$4:$AB$4>=$K5)*('Cost baseline'!$C$4:$AB$4<=$L5)*('Cost baseline'!$C$5:$AB$5=O$4))/($L5-$K5+1)) -> 0 | P5: =IF($J5=0,0,$J5*SUMPRODUCT(('Cost baseline'!$C$4:$AB$4>=$K5)*('Cost baseline'!$C$4:$AB$4<=$L5)*('Cost baseline'!$C$5:$AB$5=P$4))/($L5-$K5+1)) -> 0 | Q5: =IF($J5=0,0,$J5*SUMPRODUCT(('Cost baseline'!$C$4:$AB$4>=$K5)*('Cost baseline'!$C$4:$AB$4<=$L5)*('Cost baseline'!$C$5:$AB$5=Q$4))/($L5-$K5+1)) -> 0 | R5: =IF($J5=0,0,$J5*SUMPRODUCT(('Cost baseline'!$C$4:$AB$4>=$K5)*('Cost baseline'!$C$4:$AB$4<=$L5)*('Cost baseline'!$C$5:$AB$5=R$4))/($L5-$K5+1)) -> 0
B6: 1.1.1 | C6: =IFERROR(INDEX(WBS!$F$5:$F$44,MATCH($B6,WBS!$B$5:$B$44,0)),"") -> – | D6: 4 thành viên × 1 ngày | E6: Nhân sự | F6: NB | G6: 4 | H6: ngày công | I6: =INDEX('Nguồn lực'!$D$5:$D$8,MATCH($F6,'Nguồn lực'!$B$5:$B$8,0)) -> 1 | J6: =G6*I6 -> 4 | K6: 1 | L6: 1 | M6: =IF($J6=0,0,$J6*SUMPRODUCT(('Cost baseline'!$C$4:$AB$4>=$K6)*('Cost baseline'!$C$4:$AB$4<=$L6)*('Cost baseline'!$C$5:$AB$5=M$4))/($L6-$K6+1)) -> 4 | N6: =IF($J6=0,0,$J6*SUMPRODUCT(('Cost baseline'!$C$4:$AB$4>=$K6)*('Cost baseline'!$C$4:$AB$4<=$L6)*('Cost baseline'!$C$5:$AB$5=N$4))/($L6-$K6+1)) -> 0 | O6: =IF($J6=0,0,$J6*SUMPRODUCT(('Cost baseline'!$C$4:$AB$4>=$K6)*('Cost baseline'!$C$4:$AB$4<=$L6)*('Cost baseline'!$C$5:$AB$5=O$4))/($L6-$K6+1)) -> 0 | P6: =IF($J6=0,0,$J6*SUMPRODUCT(('Cost baseline'!$C$4:$AB$4>=$K6)*('Cost baseline'!$C$4:$AB$4<=$L6)*('Cost baseline'!$C$5:$AB$5=P$4))/($L6-$K6+1)) -> 0 | Q6: =IF($J6=0,0,$J6*SUMPRODUCT(('Cost baseline'!$C$4:$AB$4>=$K6)*('Cost baseline'!$C$4:$AB$4<=$L6)*('Cost baseline'!$C$5:$AB$5=Q$4))/($L6-$K6+1)) -> 0 | R6: =IF($J6=0,0,$J6*SUMPRODUCT(('Cost baseline'!$C$4:$AB$4>=$K6)*('Cost baseline'!$C$4:$AB$4<=$L6)*('Cost baseline'!$C$5:$AB$5=R$4))/($L6-$K6+1)) -> 0
B7: 1.1.2 | C7: =IFERROR(INDEX(WBS!$F$5:$F$44,MATCH($B7,WBS!$B$5:$B$44,0)),"") -> – | D7: PM lập kế hoạch dự án | E7: Nhân sự | F7: PM | G7: 8 | H7: ngày công | I7: =INDEX('Nguồn lực'!$D$5:$D$8,MATCH($F7,'Nguồn lực'!$B$5:$B$8,0)) -> 1.5 | J7: =G7*I7 -> 12 | K7: 1 | L7: 6 | M7: =IF($J7=0,0,$J7*SUMPRODUCT(('Cost baseline'!$C$4:$AB$4>=$K7)*('Cost baseline'!$C$4:$AB$4<=$L7)*('Cost baseline'!$C$5:$AB$5=M$4))/($L7-$K7+1)) -> 10 | N7: =IF($J7=0,0,$J7*SUMPRODUCT(('Cost baseline'!$C$4:$AB$4>=$K7)*('Cost baseline'!$C$4:$AB$4<=$L7)*('Cost baseline'!$C$5:$AB$5=N$4))/($L7-$K7+1)) -> 2 | O7: =IF($J7=0,0,$J7*SUMPRODUCT(('Cost baseline'!$C$4:$AB$4>=$K7)*('Cost baseline'!$C$4:$AB$4<=$L7)*('Cost baseline'!$C$5:$AB$5=O$4))/($L7-$K7+1)) -> 0 | P7: =IF($J7=0,0,$J7*SUMPRODUCT(('Cost baseline'!$C$4:$AB$4>=$K7)*('Cost baseline'!$C$4:$AB$4<=$L7)*('Cost baseline'!$C$5:$AB$5=P$4))/($L7-$K7+1)) -> 0 | Q7: =IF($J7=0,0,$J7*SUMPRODUCT(('Cost baseline'!$C$4:$AB$4>=$K7)*('Cost baseline'!$C$4:$AB$4<=$L7)*('Cost baseline'!$C$5:$AB$5=Q$4))/($L7-$K7+1)) -> 0 | R7: =IF($J7=0,0,$J7*SUMPRODUCT(('Cost baseline'!$C$4:$AB$4>=$K7)*('Cost baseline'!$C$4:$AB$4<=$L7)*('Cost baseline'!$C$5:$AB$5=R$4))/($L7-$K7+1)) -> 0
B8: 1.1.2 | C8: =IFERROR(INDEX(WBS!$F$5:$F$44,MATCH($B8,WBS!$B$5:$B$44,0)),"") -> – | D8: 4 thành viên: lịch, chi phí, chất lượng | E8: Nhân sự | F8: NB | G8: 10 | H8: ngày công | I8: =INDEX('Nguồn lực'!$D$5:$D$8,MATCH($F8,'Nguồn lực'!$B$5:$B$8,0)) -> 1 | J8: =G8*I8 -> 10 | K8: 1 | L8: 6 | M8: =IF($J8=0,0,$J8*SUMPRODUCT(('Cost baseline'!$C$4:$AB$4>=$K8)*('Cost baseline'!$C$4:$AB$4<=$L8)*('Cost baseline'!$C$5:$AB$5=M$4))/($L8-$K8+1)) -> 8.3333333 | N8: =IF($J8=0,0,$J8*SUMPRODUCT(('Cost baseline'!$C$4:$AB$4>=$K8)*('Cost baseline'!$C$4:$AB$4<=$L8)*('Cost baseline'!$C$5:$AB$5=N$4))/($L8-$K8+1)) -> 1.6666667 | O8: =IF($J8=0,0,$J8*SUMPRODUCT(('Cost baseline'!$C$4:$AB$4>=$K8)*('Cost baseline'!$C$4:$AB$4<=$L8)*('Cost baseline'!$C$5:$AB$5=O$4))/($L8-$K8+1)) -> 0 | P8: =IF($J8=0,0,$J8*SUMPRODUCT(('Cost baseline'!$C$4:$AB$4>=$K8)*('Cost baseline'!$C$4:$AB$4<=$L8)*('Cost baseline'!$C$5:$AB$5=P$4))/($L8-$K8+1)) -> 0 | Q8: =IF($J8=0,0,$J8*SUMPRODUCT(('Cost baseline'!$C$4:$AB$4>=$K8)*('Cost baseline'!$C$4:$AB$4<=$L8)*('Cost baseline'!$C$5:$AB$5=Q$4))/($L8-$K8+1)) -> 0 | R8: =IF($J8=0,0,$J8*SUMPRODUCT(('Cost baseline'!$C$4:$AB$4>=$K8)*('Cost baseline'!$C$4:$AB$4<=$L8)*('Cost baseline'!$C$5:$AB$5=R$4))/($L8-$K8+1)) -> 0
B9: 1.1.3 | C9: =IFERROR(INDEX(WBS!$F$5:$F$44,MATCH($B9,WBS!$B$5:$B$44,0)),"") -> – | D9: PM đàm phán hợp đồng | E9: Nhân sự | F9: PM | G9: 3 | H9: ngày công | I9: =INDEX('Nguồn lực'!$D$5:$D$8,MATCH($F9,'Nguồn lực'!$B$5:$B$8,0)) -> 1.5 | J9: =G9*I9 -> 4.5 | K9: 1 | L9: 4 | M9: =IF($J9=0,0,$J9*SUMPRODUCT(('Cost baseline'!$C$4:$AB$4>=$K9)*('Cost baseline'!$C$4:$AB$4<=$L9)*('Cost baseline'!$C$5:$AB$5=M$4))/($L9-$K9+1)) -> 4.5 | N9: =IF($J9=0,0,$J9*SUMPRODUCT(('Cost baseline'!$C$4:$AB$4>=$K9)*('Cost baseline'!$C$4:$AB$4<=$L9)*('Cost baseline'!$C$5:$AB$5=N$4))/($L9-$K9+1)) -> 0 | O9: =IF($J9=0,0,$J9*SUMPRODUCT(('Cost baseline'!$C$4:$AB$4>=$K9)*('Cost baseline'!$C$4:$AB$4<=$L9)*('Cost baseline'!$C$5:$AB$5=O$4))/($L9-$K9+1)) -> 0 | P9: =IF($J9=0,0,$J9*SUMPRODUCT(('Cost baseline'!$C$4:$AB$4>=$K9)*('Cost baseline'!$C$4:$AB$4<=$L9)*('Cost baseline'!$C$5:$AB$5=P$4))/($L9-$K9+1)) -> 0 | Q9: =IF($J9=0,0,$J9*SUMPRODUCT(('Cost baseline'!$C$4:$AB$4>=$K9)*('Cost baseline'!$C$4:$AB$4<=$L9)*('Cost baseline'!$C$5:$AB$5=Q$4))/($L9-$K9+1)) -> 0 | R9: =IF($J9=0,0,$J9*SUMPRODUCT(('Cost baseline'!$C$4:$AB$4>=$K9)*('Cost baseline'!$C$4:$AB$4<=$L9)*('Cost baseline'!$C$5:$AB$5=R$4))/($L9-$K9+1)) -> 0
B10: 1.1.3 | C10: =IFERROR(INDEX(WBS!$F$5:$F$44,MATCH($B10,WBS!$B$5:$B$44,0)),"") -> – | D10: Lê Anh: chào giá, hợp đồng | E10: Nhân sự | F10: NB | G10: 6 | H10: ngày công | I10: =INDEX('Nguồn lực'!$D$5:$D$8,MATCH($F10,'Nguồn lực'!$B$5:$B$8,0)) -> 1 | J10: =G10*I10 -> 6 | K10: 1 | L10: 4 | M10: =IF($J10=0,0,$J10*SUMPRODUCT(('Cost baseline'!$C$4:$AB$4>=$K10)*('Cost baseline'!$C$4:$AB$4<=$L10)*('Cost baseline'!$C$5:$AB$5=M$4))/($L10-$K10+1)) -> 6 | N10: =IF($J10=0,0,$J10*SUMPRODUCT(('Cost baseline'!$C$4:$AB$4>=$K10)*('Cost baseline'!$C$4:$AB$4<=$L10)*('Cost baseline'!$C$5:$AB$5=N$4))/($L10-$K10+1)) -> 0 | O10: =IF($J10=0,0,$J10*SUMPRODUCT(('Cost baseline'!$C$4:$AB$4>=$K10)*('Cost baseline'!$C$4:$AB$4<=$L10)*('Cost baseline'!$C$5:$AB$5=O$4))/($L10-$K10+1)) -> 0 | P10: =IF($J10=0,0,$J10*SUMPRODUCT(('Cost baseline'!$C$4:$AB$4>=$K10)*('Cost baseline'!$C$4:$AB$4<=$L10)*('Cost baseline'!$C$5:$AB$5=P$4))/($L10-$K10+1)) -> 0 | Q10: =IF($J10=0,0,$J10*SUMPRODUCT(('Cost baseline'!$C$4:$AB$4>=$K10)*('Cost baseline'!$C$4:$AB$4<=$L10)*('Cost baseline'!$C$5:$AB$5=Q$4))/($L10-$K10+1)) -> 0 | R10: =IF($J10=0,0,$J10*SUMPRODUCT(('Cost baseline'!$C$4:$AB$4>=$K10)*('Cost baseline'!$C$4:$AB$4<=$L10)*('Cost baseline'!$C$5:$AB$5=R$4))/($L10-$K10+1)) -> 0
B11: 1.2.1 | C11: =IFERROR(INDEX(WBS!$F$5:$F$44,MATCH($B11,WBS!$B$5:$B$44,0)),"") -> – | D11: PM 0,5 ngày/tuần | E11: Nhân sự | F11: PM | G11: 13 | H11: ngày công | I11: =INDEX('Nguồn lực'!$D$5:$D$8,MATCH($F11,'Nguồn lực'!$B$5:$B$8,0)) -> 1.5 | J11: =G11*I11 -> 19.5 | K11: 1 | L11: 26 | M11: =IF($J11=0,0,$J11*SUMPRODUCT(('Cost baseline'!$C$4:$AB$4>=$K11)*('Cost baseline'!$C$4:$AB$4<=$L11)*('Cost baseline'!$C$5:$AB$5=M$4))/($L11-$K11+1)) -> 3.75 | N11: =IF($J11=0,0,$J11*SUMPRODUCT(('Cost baseline'!$C$4:$AB$4>=$K11)*('Cost baseline'!$C$4:$AB$4<=$L11)*('Cost baseline'!$C$5:$AB$5=N$4))/($L11-$K11+1)) -> 3 | O11: =IF($J11=0,0,$J11*SUMPRODUCT(('Cost baseline'!$C$4:$AB$4>=$K11)*('Cost baseline'!$C$4:$AB$4<=$L11)*('Cost baseline'!$C$5:$AB$5=O$4))/($L11-$K11+1)) -> 3 | P11: =IF($J11=0,0,$J11*SUMPRODUCT(('Cost baseline'!$C$4:$AB$4>=$K11)*('Cost baseline'!$C$4:$AB$4<=$L11)*('Cost baseline'!$C$5:$AB$5=P$4))/($L11-$K11+1)) -> 3.75 | Q11: =IF($J11=0,0,$J11*SUMPRODUCT(('Cost baseline'!$C$4:$AB$4>=$K11)*('Cost baseline'!$C$4:$AB$4<=$L11)*('Cost baseline'!$C$5:$AB$5=Q$4))/($L11-$K11+1)) -> 3 | R11: =IF($J11=0,0,$J11*SUMPRODUCT(('Cost baseline'!$C$4:$AB$4>=$K11)*('Cost baseline'!$C$4:$AB$4<=$L11)*('Cost baseline'!$C$5:$AB$5=R$4))/($L11-$K11+1)) -> 3
B12: 1.2.1 | C12: =IFERROR(INDEX(WBS!$F$5:$F$44,MATCH($B12,WBS!$B$5:$B$44,0)),"") -> – | D12: Tuấn Anh 0,5 ngày/tuần: báo cáo, EVM | E12: Nhân sự | F12: NB | G12: 13 | H12: ngày công | I12: =INDEX('Nguồn lực'!$D$5:$D$8,MATCH($F12,'Nguồn lực'!$B$5:$B$8,0)) -> 1 | J12: =G12*I12 -> 13 | K12: 1 | L12: 26 | M12: =IF($J12=0,0,$J12*SUMPRODUCT(('Cost baseline'!$C$4:$AB$4>=$K12)*('Cost baseline'!$C$4:$AB$4<=$L12)*('Cost baseline'!$C$5:$AB$5=M$4))/($L12-$K12+1)) -> 2.5 | N12: =IF($J12=0,0,$J12*SUMPRODUCT(('Cost baseline'!$C$4:$AB$4>=$K12)*('Cost baseline'!$C$4:$AB$4<=$L12)*('Cost baseline'!$C$5:$AB$5=N$4))/($L12-$K12+1)) -> 2 | O12: =IF($J12=0,0,$J12*SUMPRODUCT(('Cost baseline'!$C$4:$AB$4>=$K12)*('Cost baseline'!$C$4:$AB$4<=$L12)*('Cost baseline'!$C$5:$AB$5=O$4))/($L12-$K12+1)) -> 2 | P12: =IF($J12=0,0,$J12*SUMPRODUCT(('Cost baseline'!$C$4:$AB$4>=$K12)*('Cost baseline'!$C$4:$AB$4<=$L12)*('Cost baseline'!$C$5:$AB$5=P$4))/($L12-$K12+1)) -> 2.5 | Q12: =IF($J12=0,0,$J12*SUMPRODUCT(('Cost baseline'!$C$4:$AB$4>=$K12)*('Cost baseline'!$C$4:$AB$4<=$L12)*('Cost baseline'!$C$5:$AB$5=Q$4))/($L12-$K12+1)) -> 2 | R12: =IF($J12=0,0,$J12*SUMPRODUCT(('Cost baseline'!$C$4:$AB$4>=$K12)*('Cost baseline'!$C$4:$AB$4<=$L12)*('Cost baseline'!$C$5:$AB$5=R$4))/($L12-$K12+1)) -> 2
B13: 1.2.2 | C13: =IFERROR(INDEX(WBS!$F$5:$F$44,MATCH($B13,WBS!$B$5:$B$44,0)),"") -> – | D13: PM: họp CCB 2 tuần/lần | E13: Nhân sự | F13: PM | G13: 6 | H13: ngày công | I13: =INDEX('Nguồn lực'!$D$5:$D$8,MATCH($F13,'Nguồn lực'!$B$5:$B$8,0)) -> 1.5 | J13: =G13*I13 -> 9 | K13: 1 | L13: 26 | M13: =IF($J13=0,0,$J13*SUMPRODUCT(('Cost baseline'!$C$4:$AB$4>=$K13)*('Cost baseline'!$C$4:$AB$4<=$L13)*('Cost baseline'!$C$5:$AB$5=M$4))/($L13-$K13+1)) -> 1.7307692 | N13: =IF($J13=0,0,$J13*SUMPRODUCT(('Cost baseline'!$C$4:$AB$4>=$K13)*('Cost baseline'!$C$4:$AB$4<=$L13)*('Cost baseline'!$C$5:$AB$5=N$4))/($L13-$K13+1)) -> 1.3846154 | O13: =IF($J13=0,0,$J13*SUMPRODUCT(('Cost baseline'!$C$4:$AB$4>=$K13)*('Cost baseline'!$C$4:$AB$4<=$L13)*('Cost baseline'!$C$5:$AB$5=O$4))/($L13-$K13+1)) -> 1.3846154 | P13: =IF($J13=0,0,$J13*SUMPRODUCT(('Cost baseline'!$C$4:$AB$4>=$K13)*('Cost baseline'!$C$4:$AB$4<=$L13)*('Cost baseline'!$C$5:$AB$5=P$4))/($L13-$K13+1)) -> 1.7307692 | Q13: =IF($J13=0,0,$J13*SUMPRODUCT(('Cost baseline'!$C$4:$AB$4>=$K13)*('Cost baseline'!$C$4:$AB$4<=$L13)*('Cost baseline'!$C$5:$AB$5=Q$4))/($L13-$K13+1)) -> 1.3846154 | R13: =IF($J13=0,0,$J13*SUMPRODUCT(('Cost baseline'!$C$4:$AB$4>=$K13)*('Cost baseline'!$C$4:$AB$4<=$L13)*('Cost baseline'!$C$5:$AB$5=R$4))/($L13-$K13+1)) -> 1.3846154
B14: 1.2.2 | C14: =IFERROR(INDEX(WBS!$F$5:$F$44,MATCH($B14,WBS!$B$5:$B$44,0)),"") -> – | D14: Quang Hiếu 0,5 ngày/tuần: thay đổi, rủi ro | E14: Nhân sự | F14: NB | G14: 13 | H14: ngày công | I14: =INDEX('Nguồn lực'!$D$5:$D$8,MATCH($F14,'Nguồn lực'!$B$5:$B$8,0)) -> 1 | J14: =G14*I14 -> 13 | K14: 1 | L14: 26 | M14: =IF($J14=0,0,$J14*SUMPRODUCT(('Cost baseline'!$C$4:$AB$4>=$K14)*('Cost baseline'!$C$4:$AB$4<=$L14)*('Cost baseline'!$C$5:$AB$5=M$4))/($L14-$K14+1)) -> 2.5 | N14: =IF($J14=0,0,$J14*SUMPRODUCT(('Cost baseline'!$C$4:$AB$4>=$K14)*('Cost baseline'!$C$4:$AB$4<=$L14)*('Cost baseline'!$C$5:$AB$5=N$4))/($L14-$K14+1)) -> 2 | O14: =IF($J14=0,0,$J14*SUMPRODUCT(('Cost baseline'!$C$4:$AB$4>=$K14)*('Cost baseline'!$C$4:$AB$4<=$L14)*('Cost baseline'!$C$5:$AB$5=O$4))/($L14-$K14+1)) -> 2 | P14: =IF($J14=0,0,$J14*SUMPRODUCT(('Cost baseline'!$C$4:$AB$4>=$K14)*('Cost baseline'!$C$4:$AB$4<=$L14)*('Cost baseline'!$C$5:$AB$5=P$4))/($L14-$K14+1)) -> 2.5 | Q14: =IF($J14=0,0,$J14*SUMPRODUCT(('Cost baseline'!$C$4:$AB$4>=$K14)*('Cost baseline'!$C$4:$AB$4<=$L14)*('Cost baseline'!$C$5:$AB$5=Q$4))/($L14-$K14+1)) -> 2 | R14: =IF($J14=0,0,$J14*SUMPRODUCT(('Cost baseline'!$C$4:$AB$4>=$K14)*('Cost baseline'!$C$4:$AB$4<=$L14)*('Cost baseline'!$C$5:$AB$5=R$4))/($L14-$K14+1)) -> 2
B15: 2.1 | C15: =IFERROR(INDEX(WBS!$F$5:$F$44,MATCH($B15,WBS!$B$5:$B$44,0)),"") -> A | D15: BA: 5 nhà hàng × 2 ngày | E15: Nhân sự | F15: BA | G15: 10 | H15: ngày công | I15: =INDEX('Nguồn lực'!$D$5:$D$8,MATCH($F15,'Nguồn lực'!$B$5:$B$8,0)) -> 1.5 | J15: =G15*I15 -> 15 | K15: =INDEX('Hoạt động, lịch'!$L$5:$L$26,MATCH($C15,'Hoạt động, lịch'!$B$5:$B$26,0))+1 -> 1 | L15: =INDEX('Hoạt động, lịch'!$M$5:$M$26,MATCH($C15,'Hoạt động, lịch'!$B$5:$B$26,0)) -> 3 | M15: =IF($J15=0,0,$J15*SUMPRODUCT(('Cost baseline'!$C$4:$AB$4>=$K15)*('Cost baseline'!$C$4:$AB$4<=$L15)*('Cost baseline'!$C$5:$AB$5=M$4))/($L15-$K15+1)) -> 15 | N15: =IF($J15=0,0,$J15*SUMPRODUCT(('Cost baseline'!$C$4:$AB$4>=$K15)*('Cost baseline'!$C$4:$AB$4<=$L15)*('Cost baseline'!$C$5:$AB$5=N$4))/($L15-$K15+1)) -> 0 | O15: =IF($J15=0,0,$J15*SUMPRODUCT(('Cost baseline'!$C$4:$AB$4>=$K15)*('Cost baseline'!$C$4:$AB$4<=$L15)*('Cost baseline'!$C$5:$AB$5=O$4))/($L15-$K15+1)) -> 0 | P15: =IF($J15=0,0,$J15*SUMPRODUCT(('Cost baseline'!$C$4:$AB$4>=$K15)*('Cost baseline'!$C$4:$AB$4<=$L15)*('Cost baseline'!$C$5:$AB$5=P$4))/($L15-$K15+1)) -> 0 | Q15: =IF($J15=0,0,$J15*SUMPRODUCT(('Cost baseline'!$C$4:$AB$4>=$K15)*('Cost baseline'!$C$4:$AB$4<=$L15)*('Cost baseline'!$C$5:$AB$5=Q$4))/($L15-$K15+1)) -> 0 | R15: =IF($J15=0,0,$J15*SUMPRODUCT(('Cost baseline'!$C$4:$AB$4>=$K15)*('Cost baseline'!$C$4:$AB$4<=$L15)*('Cost baseline'!$C$5:$AB$5=R$4))/($L15-$K15+1)) -> 0
B16: 2.1 | C16: =IFERROR(INDEX(WBS!$F$5:$F$44,MATCH($B16,WBS!$B$5:$B$44,0)),"") -> A | D16: Đức Anh đi cùng khảo sát | E16: Nhân sự | F16: NB | G16: 10 | H16: ngày công | I16: =INDEX('Nguồn lực'!$D$5:$D$8,MATCH($F16,'Nguồn lực'!$B$5:$B$8,0)) -> 1 | J16: =G16*I16 -> 10 | K16: =INDEX('Hoạt động, lịch'!$L$5:$L$26,MATCH($C16,'Hoạt động, lịch'!$B$5:$B$26,0))+1 -> 1 | L16: =INDEX('Hoạt động, lịch'!$M$5:$M$26,MATCH($C16,'Hoạt động, lịch'!$B$5:$B$26,0)) -> 3 | M16: =IF($J16=0,0,$J16*SUMPRODUCT(('Cost baseline'!$C$4:$AB$4>=$K16)*('Cost baseline'!$C$4:$AB$4<=$L16)*('Cost baseline'!$C$5:$AB$5=M$4))/($L16-$K16+1)) -> 10 | N16: =IF($J16=0,0,$J16*SUMPRODUCT(('Cost baseline'!$C$4:$AB$4>=$K16)*('Cost baseline'!$C$4:$AB$4<=$L16)*('Cost baseline'!$C$5:$AB$5=N$4))/($L16-$K16+1)) -> 0 | O16: =IF($J16=0,0,$J16*SUMPRODUCT(('Cost baseline'!$C$4:$AB$4>=$K16)*('Cost baseline'!$C$4:$AB$4<=$L16)*('Cost baseline'!$C$5:$AB$5=O$4))/($L16-$K16+1)) -> 0 | P16: =IF($J16=0,0,$J16*SUMPRODUCT(('Cost baseline'!$C$4:$AB$4>=$K16)*('Cost baseline'!$C$4:$AB$4<=$L16)*('Cost baseline'!$C$5:$AB$5=P$4))/($L16-$K16+1)) -> 0 | Q16: =IF($J16=0,0,$J16*SUMPRODUCT(('Cost baseline'!$C$4:$AB$4>=$K16)*('Cost baseline'!$C$4:$AB$4<=$L16)*('Cost baseline'!$C$5:$AB$5=Q$4))/($L16-$K16+1)) -> 0 | R16: =IF($J16=0,0,$J16*SUMPRODUCT(('Cost baseline'!$C$4:$AB$4>=$K16)*('Cost baseline'!$C$4:$AB$4<=$L16)*('Cost baseline'!$C$5:$AB$5=R$4))/($L16-$K16+1)) -> 0
B17: 2.2 | C17: =IFERROR(INDEX(WBS!$F$5:$F$44,MATCH($B17,WBS!$B$5:$B$44,0)),"") -> B | D17: BA viết SRS, workshop | E17: Nhân sự | F17: BA | G17: 15 | H17: ngày công | I17: =INDEX('Nguồn lực'!$D$5:$D$8,MATCH($F17,'Nguồn lực'!$B$5:$B$8,0)) -> 1.5 | J17: =G17*I17 -> 22.5 | K17: =INDEX('Hoạt động, lịch'!$L$5:$L$26,MATCH($C17,'Hoạt động, lịch'!$B$5:$B$26,0))+1 -> 4 | L17: =INDEX('Hoạt động, lịch'!$M$5:$M$26,MATCH($C17,'Hoạt động, lịch'!$B$5:$B$26,0)) -> 6 | M17: =IF($J17=0,0,$J17*SUMPRODUCT(('Cost baseline'!$C$4:$AB$4>=$K17)*('Cost baseline'!$C$4:$AB$4<=$L17)*('Cost baseline'!$C$5:$AB$5=M$4))/($L17-$K17+1)) -> 15 | N17: =IF($J17=0,0,$J17*SUMPRODUCT(('Cost baseline'!$C$4:$AB$4>=$K17)*('Cost baseline'!$C$4:$AB$4<=$L17)*('Cost baseline'!$C$5:$AB$5=N$4))/($L17-$K17+1)) -> 7.5 | O17: =IF($J17=0,0,$J17*SUMPRODUCT(('Cost baseline'!$C$4:$AB$4>=$K17)*('Cost baseline'!$C$4:$AB$4<=$L17)*('Cost baseline'!$C$5:$AB$5=O$4))/($L17-$K17+1)) -> 0 | P17: =IF($J17=0,0,$J17*SUMPRODUCT(('Cost baseline'!$C$4:$AB$4>=$K17)*('Cost baseline'!$C$4:$AB$4<=$L17)*('Cost baseline'!$C$5:$AB$5=P$4))/($L17-$K17+1)) -> 0 | Q17: =IF($J17=0,0,$J17*SUMPRODUCT(('Cost baseline'!$C$4:$AB$4>=$K17)*('Cost baseline'!$C$4:$AB$4<=$L17)*('Cost baseline'!$C$5:$AB$5=Q$4))/($L17-$K17+1)) -> 0 | R17: =IF($J17=0,0,$J17*SUMPRODUCT(('Cost baseline'!$C$4:$AB$4>=$K17)*('Cost baseline'!$C$4:$AB$4<=$L17)*('Cost baseline'!$C$5:$AB$5=R$4))/($L17-$K17+1)) -> 0
B18: 2.2 | C18: =IFERROR(INDEX(WBS!$F$5:$F$44,MATCH($B18,WBS!$B$5:$B$44,0)),"") -> B | D18: Đức Anh: rà soát, ma trận truy vết | E18: Nhân sự | F18: NB | G18: 8 | H18: ngày công | I18: =INDEX('Nguồn lực'!$D$5:$D$8,MATCH($F18,'Nguồn lực'!$B$5:$B$8,0)) -> 1 | J18: =G18*I18 -> 8 | K18: =INDEX('Hoạt động, lịch'!$L$5:$L$26,MATCH($C18,'Hoạt động, lịch'!$B$5:$B$26,0))+1 -> 4 | L18: =INDEX('Hoạt động, lịch'!$M$5:$M$26,MATCH($C18,'Hoạt động, lịch'!$B$5:$B$26,0)) -> 6 | M18: =IF($J18=0,0,$J18*SUMPRODUCT(('Cost baseline'!$C$4:$AB$4>=$K18)*('Cost baseline'!$C$4:$AB$4<=$L18)*('Cost baseline'!$C$5:$AB$5=M$4))/($L18-$K18+1)) -> 5.3333333 | N18: =IF($J18=0,0,$J18*SUMPRODUCT(('Cost baseline'!$C$4:$AB$4>=$K18)*('Cost baseline'!$C$4:$AB$4<=$L18)*('Cost baseline'!$C$5:$AB$5=N$4))/($L18-$K18+1)) -> 2.6666667 | O18: =IF($J18=0,0,$J18*SUMPRODUCT(('Cost baseline'!$C$4:$AB$4>=$K18)*('Cost baseline'!$C$4:$AB$4<=$L18)*('Cost baseline'!$C$5:$AB$5=O$4))/($L18-$K18+1)) -> 0 | P18: =IF($J18=0,0,$J18*SUMPRODUCT(('Cost baseline'!$C$4:$AB$4>=$K18)*('Cost baseline'!$C$4:$AB$4<=$L18)*('Cost baseline'!$C$5:$AB$5=P$4))/($L18-$K18+1)) -> 0 | Q18: =IF($J18=0,0,$J18*SUMPRODUCT(('Cost baseline'!$C$4:$AB$4>=$K18)*('Cost baseline'!$C$4:$AB$4<=$L18)*('Cost baseline'!$C$5:$AB$5=Q$4))/($L18-$K18+1)) -> 0 | R18: =IF($J18=0,0,$J18*SUMPRODUCT(('Cost baseline'!$C$4:$AB$4>=$K18)*('Cost baseline'!$C$4:$AB$4<=$L18)*('Cost baseline'!$C$5:$AB$5=R$4))/($L18-$K18+1)) -> 0
B19: 3.1 | C19: =IFERROR(INDEX(WBS!$F$5:$F$44,MATCH($B19,WBS!$B$5:$B$44,0)),"") -> C | D19: 2 tư vấn × 10 ngày | E19: Nhân sự | F19: TV | G19: 20 | H19: ngày công | I19: =INDEX('Nguồn lực'!$D$5:$D$8,MATCH($F19,'Nguồn lực'!$B$5:$B$8,0)) -> 2 | J19: =G19*I19 -> 40 | K19: =INDEX('Hoạt động, lịch'!$L$5:$L$26,MATCH($C19,'Hoạt động, lịch'!$B$5:$B$26,0))+1 -> 7 | L19: =INDEX('Hoạt động, lịch'!$M$5:$M$26,MATCH($C19,'Hoạt động, lịch'!$B$5:$B$26,0)) -> 8 | M19: =IF($J19=0,0,$J19*SUMPRODUCT(('Cost baseline'!$C$4:$AB$4>=$K19)*('Cost baseline'!$C$4:$AB$4<=$L19)*('Cost baseline'!$C$5:$AB$5=M$4))/($L19-$K19+1)) -> 0 | N19: =IF($J19=0,0,$J19*SUMPRODUCT(('Cost baseline'!$C$4:$AB$4>=$K19)*('Cost baseline'!$C$4:$AB$4<=$L19)*('Cost baseline'!$C$5:$AB$5=N$4))/($L19-$K19+1)) -> 40 | O19: =IF($J19=0,0,$J19*SUMPRODUCT(('Cost baseline'!$C$4:$AB$4>=$K19)*('Cost baseline'!$C$4:$AB$4<=$L19)*('Cost baseline'!$C$5:$AB$5=O$4))/($L19-$K19+1)) -> 0 | P19: =IF($J19=0,0,$J19*SUMPRODUCT(('Cost baseline'!$C$4:$AB$4>=$K19)*('Cost baseline'!$C$4:$AB$4<=$L19)*('Cost baseline'!$C$5:$AB$5=P$4))/($L19-$K19+1)) -> 0 | Q19: =IF($J19=0,0,$J19*SUMPRODUCT(('Cost baseline'!$C$4:$AB$4>=$K19)*('Cost baseline'!$C$4:$AB$4<=$L19)*('Cost baseline'!$C$5:$AB$5=Q$4))/($L19-$K19+1)) -> 0 | R19: =IF($J19=0,0,$J19*SUMPRODUCT(('Cost baseline'!$C$4:$AB$4>=$K19)*('Cost baseline'!$C$4:$AB$4<=$L19)*('Cost baseline'!$C$5:$AB$5=R$4))/($L19-$K19+1)) -> 0
B20: 3.1 | C20: =IFERROR(INDEX(WBS!$F$5:$F$44,MATCH($B20,WBS!$B$5:$B$44,0)),"") -> C | D20: BA chuyển giao yêu cầu | E20: Nhân sự | F20: BA | G20: 5 | H20: ngày công | I20: =INDEX('Nguồn lực'!$D$5:$D$8,MATCH($F20,'Nguồn lực'!$B$5:$B$8,0)) -> 1.5 | J20: =G20*I20 -> 7.5 | K20: =INDEX('Hoạt động, lịch'!$L$5:$L$26,MATCH($C20,'Hoạt động, lịch'!$B$5:$B$26,0))+1 -> 7 | L20: =INDEX('Hoạt động, lịch'!$M$5:$M$26,MATCH($C20,'Hoạt động, lịch'!$B$5:$B$26,0)) -> 8 | M20: =IF($J20=0,0,$J20*SUMPRODUCT(('Cost baseline'!$C$4:$AB$4>=$K20)*('Cost baseline'!$C$4:$AB$4<=$L20)*('Cost baseline'!$C$5:$AB$5=M$4))/($L20-$K20+1)) -> 0 | N20: =IF($J20=0,0,$J20*SUMPRODUCT(('Cost baseline'!$C$4:$AB$4>=$K20)*('Cost baseline'!$C$4:$AB$4<=$L20)*('Cost baseline'!$C$5:$AB$5=N$4))/($L20-$K20+1)) -> 7.5 | O20: =IF($J20=0,0,$J20*SUMPRODUCT(('Cost baseline'!$C$4:$AB$4>=$K20)*('Cost baseline'!$C$4:$AB$4<=$L20)*('Cost baseline'!$C$5:$AB$5=O$4))/($L20-$K20+1)) -> 0 | P20: =IF($J20=0,0,$J20*SUMPRODUCT(('Cost baseline'!$C$4:$AB$4>=$K20)*('Cost baseline'!$C$4:$AB$4<=$L20)*('Cost baseline'!$C$5:$AB$5=P$4))/($L20-$K20+1)) -> 0 | Q20: =IF($J20=0,0,$J20*SUMPRODUCT(('Cost baseline'!$C$4:$AB$4>=$K20)*('Cost baseline'!$C$4:$AB$4<=$L20)*('Cost baseline'!$C$5:$AB$5=Q$4))/($L20-$K20+1)) -> 0 | R20: =IF($J20=0,0,$J20*SUMPRODUCT(('Cost baseline'!$C$4:$AB$4>=$K20)*('Cost baseline'!$C$4:$AB$4<=$L20)*('Cost baseline'!$C$5:$AB$5=R$4))/($L20-$K20+1)) -> 0
B21: 3.2 | C21: =IFERROR(INDEX(WBS!$F$5:$F$44,MATCH($B21,WBS!$B$5:$B$44,0)),"") -> D | D21: 1 tư vấn × 10 ngày | E21: Nhân sự | F21: TV | G21: 10 | H21: ngày công | I21: =INDEX('Nguồn lực'!$D$5:$D$8,MATCH($F21,'Nguồn lực'!$B$5:$B$8,0)) -> 2 | J21: =G21*I21 -> 20 | K21: =INDEX('Hoạt động, lịch'!$L$5:$L$26,MATCH($C21,'Hoạt động, lịch'!$B$5:$B$26,0))+1 -> 7 | L21: =INDEX('Hoạt động, lịch'!$M$5:$M$26,MATCH($C21,'Hoạt động, lịch'!$B$5:$B$26,0)) -> 8 | M21: =IF($J21=0,0,$J21*SUMPRODUCT(('Cost baseline'!$C$4:$AB$4>=$K21)*('Cost baseline'!$C$4:$AB$4<=$L21)*('Cost baseline'!$C$5:$AB$5=M$4))/($L21-$K21+1)) -> 0 | N21: =IF($J21=0,0,$J21*SUMPRODUCT(('Cost baseline'!$C$4:$AB$4>=$K21)*('Cost baseline'!$C$4:$AB$4<=$L21)*('Cost baseline'!$C$5:$AB$5=N$4))/($L21-$K21+1)) -> 20 | O21: =IF($J21=0,0,$J21*SUMPRODUCT(('Cost baseline'!$C$4:$AB$4>=$K21)*('Cost baseline'!$C$4:$AB$4<=$L21)*('Cost baseline'!$C$5:$AB$5=O$4))/($L21-$K21+1)) -> 0 | P21: =IF($J21=0,0,$J21*SUMPRODUCT(('Cost baseline'!$C$4:$AB$4>=$K21)*('Cost baseline'!$C$4:$AB$4<=$L21)*('Cost baseline'!$C$5:$AB$5=P$4))/($L21-$K21+1)) -> 0 | Q21: =IF($J21=0,0,$J21*SUMPRODUCT(('Cost baseline'!$C$4:$AB$4>=$K21)*('Cost baseline'!$C$4:$AB$4<=$L21)*('Cost baseline'!$C$5:$AB$5=Q$4))/($L21-$K21+1)) -> 0 | R21: =IF($J21=0,0,$J21*SUMPRODUCT(('Cost baseline'!$C$4:$AB$4>=$K21)*('Cost baseline'!$C$4:$AB$4<=$L21)*('Cost baseline'!$C$5:$AB$5=R$4))/($L21-$K21+1)) -> 0
B22: 3.2 | C22: =IFERROR(INDEX(WBS!$F$5:$F$44,MATCH($B22,WBS!$B$5:$B$44,0)),"") -> D | D22: BA chuyển giao yêu cầu | E22: Nhân sự | F22: BA | G22: 5 | H22: ngày công | I22: =INDEX('Nguồn lực'!$D$5:$D$8,MATCH($F22,'Nguồn lực'!$B$5:$B$8,0)) -> 1.5 | J22: =G22*I22 -> 7.5 | K22: =INDEX('Hoạt động, lịch'!$L$5:$L$26,MATCH($C22,'Hoạt động, lịch'!$B$5:$B$26,0))+1 -> 7 | L22: =INDEX('Hoạt động, lịch'!$M$5:$M$26,MATCH($C22,'Hoạt động, lịch'!$B$5:$B$26,0)) -> 8 | M22: =IF($J22=0,0,$J22*SUMPRODUCT(('Cost baseline'!$C$4:$AB$4>=$K22)*('Cost baseline'!$C$4:$AB$4<=$L22)*('Cost baseline'!$C$5:$AB$5=M$4))/($L22-$K22+1)) -> 0 | N22: =IF($J22=0,0,$J22*SUMPRODUCT(('Cost baseline'!$C$4:$AB$4>=$K22)*('Cost baseline'!$C$4:$AB$4<=$L22)*('Cost baseline'!$C$5:$AB$5=N$4))/($L22-$K22+1)) -> 7.5 | O22: =IF($J22=0,0,$J22*SUMPRODUCT(('Cost baseline'!$C$4:$AB$4>=$K22)*('Cost baseline'!$C$4:$AB$4<=$L22)*('Cost baseline'!$C$5:$AB$5=O$4))/($L22-$K22+1)) -> 0 | P22: =IF($J22=0,0,$J22*SUMPRODUCT(('Cost baseline'!$C$4:$AB$4>=$K22)*('Cost baseline'!$C$4:$AB$4<=$L22)*('Cost baseline'!$C$5:$AB$5=P$4))/($L22-$K22+1)) -> 0 | Q22: =IF($J22=0,0,$J22*SUMPRODUCT(('Cost baseline'!$C$4:$AB$4>=$K22)*('Cost baseline'!$C$4:$AB$4<=$L22)*('Cost baseline'!$C$5:$AB$5=Q$4))/($L22-$K22+1)) -> 0 | R22: =IF($J22=0,0,$J22*SUMPRODUCT(('Cost baseline'!$C$4:$AB$4>=$K22)*('Cost baseline'!$C$4:$AB$4<=$L22)*('Cost baseline'!$C$5:$AB$5=R$4))/($L22-$K22+1)) -> 0
B23: 4.1 | C23: =IFERROR(INDEX(WBS!$F$5:$F$44,MATCH($B23,WBS!$B$5:$B$44,0)),"") -> E | D23: 2 tư vấn × 30 ngày (3 vòng) | E23: Nhân sự | F23: TV | G23: 60 | H23: ngày công | I23: =INDEX('Nguồn lực'!$D$5:$D$8,MATCH($F23,'Nguồn lực'!$B$5:$B$8,0)) -> 2 | J23: =G23*I23 -> 120 | K23: =INDEX('Hoạt động, lịch'!$L$5:$L$26,MATCH($C23,'Hoạt động, lịch'!$B$5:$B$26,0))+1 -> 9 | L23: =INDEX('Hoạt động, lịch'!$M$5:$M$26,MATCH($C23,'Hoạt động, lịch'!$B$5:$B$26,0)) -> 14 | M23: =IF($J23=0,0,$J23*SUMPRODUCT(('Cost baseline'!$C$4:$AB$4>=$K23)*('Cost baseline'!$C$4:$AB$4<=$L23)*('Cost baseline'!$C$5:$AB$5=M$4))/($L23-$K23+1)) -> 0 | N23: =IF($J23=0,0,$J23*SUMPRODUCT(('Cost baseline'!$C$4:$AB$4>=$K23)*('Cost baseline'!$C$4:$AB$4<=$L23)*('Cost baseline'!$C$5:$AB$5=N$4))/($L23-$K23+1)) -> 20 | O23: =IF($J23=0,0,$J23*SUMPRODUCT(('Cost baseline'!$C$4:$AB$4>=$K23)*('Cost baseline'!$C$4:$AB$4<=$L23)*('Cost baseline'!$C$5:$AB$5=O$4))/($L23-$K23+1)) -> 80 | P23: =IF($J23=0,0,$J23*SUMPRODUCT(('Cost baseline'!$C$4:$AB$4>=$K23)*('Cost baseline'!$C$4:$AB$4<=$L23)*('Cost baseline'!$C$5:$AB$5=P$4))/($L23-$K23+1)) -> 20 | Q23: =IF($J23=0,0,$J23*SUMPRODUCT(('Cost baseline'!$C$4:$AB$4>=$K23)*('Cost baseline'!$C$4:$AB$4<=$L23)*('Cost baseline'!$C$5:$AB$5=Q$4))/($L23-$K23+1)) -> 0 | R23: =IF($J23=0,0,$J23*SUMPRODUCT(('Cost baseline'!$C$4:$AB$4>=$K23)*('Cost baseline'!$C$4:$AB$4<=$L23)*('Cost baseline'!$C$5:$AB$5=R$4))/($L23-$K23+1)) -> 0
B24: 4.1 | C24: =IFERROR(INDEX(WBS!$F$5:$F$44,MATCH($B24,WBS!$B$5:$B$44,0)),"") -> E | D24: Phí khởi tạo nền tảng, chuyển dữ liệu | E24: Phần mềm, dịch vụ | G24: 1 | H24: gói | I24: 30 | J24: =G24*I24 -> 30 | K24: =INDEX('Hoạt động, lịch'!$L$5:$L$26,MATCH($C24,'Hoạt động, lịch'!$B$5:$B$26,0))+1 -> 9 | L24: =INDEX('Hoạt động, lịch'!$M$5:$M$26,MATCH($C24,'Hoạt động, lịch'!$B$5:$B$26,0)) -> 14 | M24: =IF($J24=0,0,$J24*SUMPRODUCT(('Cost baseline'!$C$4:$AB$4>=$K24)*('Cost baseline'!$C$4:$AB$4<=$L24)*('Cost baseline'!$C$5:$AB$5=M$4))/($L24-$K24+1)) -> 0 | N24: =IF($J24=0,0,$J24*SUMPRODUCT(('Cost baseline'!$C$4:$AB$4>=$K24)*('Cost baseline'!$C$4:$AB$4<=$L24)*('Cost baseline'!$C$5:$AB$5=N$4))/($L24-$K24+1)) -> 5 | O24: =IF($J24=0,0,$J24*SUMPRODUCT(('Cost baseline'!$C$4:$AB$4>=$K24)*('Cost baseline'!$C$4:$AB$4<=$L24)*('Cost baseline'!$C$5:$AB$5=O$4))/($L24-$K24+1)) -> 20 | P24: =IF($J24=0,0,$J24*SUMPRODUCT(('Cost baseline'!$C$4:$AB$4>=$K24)*('Cost baseline'!$C$4:$AB$4<=$L24)*('Cost baseline'!$C$5:$AB$5=P$4))/($L24-$K24+1)) -> 5 | Q24: =IF($J24=0,0,$J24*SUMPRODUCT(('Cost baseline'!$C$4:$AB$4>=$K24)*('Cost baseline'!$C$4:$AB$4<=$L24)*('Cost baseline'!$C$5:$AB$5=Q$4))/($L24-$K24+1)) -> 0 | R24: =IF($J24=0,0,$J24*SUMPRODUCT(('Cost baseline'!$C$4:$AB$4>=$K24)*('Cost baseline'!$C$4:$AB$4<=$L24)*('Cost baseline'!$C$5:$AB$5=R$4))/($L24-$K24+1)) -> 0
B25: 4.1 | C25: =IFERROR(INDEX(WBS!$F$5:$F$44,MATCH($B25,WBS!$B$5:$B$44,0)),"") -> E | D25: Môi trường thử (tuần 9 – 16) | E25: Phần mềm, dịch vụ | G25: 2 | H25: tháng | I25: 3 | J25: =G25*I25 -> 6 | K25: 9 | L25: 16 | M25: =IF($J25=0,0,$J25*SUMPRODUCT(('Cost baseline'!$C$4:$AB$4>=$K25)*('Cost baseline'!$C$4:$AB$4<=$L25)*('Cost baseline'!$C$5:$AB$5=M$4))/($L25-$K25+1)) -> 0 | N25: =IF($J25=0,0,$J25*SUMPRODUCT(('Cost baseline'!$C$4:$AB$4>=$K25)*('Cost baseline'!$C$4:$AB$4<=$L25)*('Cost baseline'!$C$5:$AB$5=N$4))/($L25-$K25+1)) -> 0.75 | O25: =IF($J25=0,0,$J25*SUMPRODUCT(('Cost baseline'!$C$4:$AB$4>=$K25)*('Cost baseline'!$C$4:$AB$4<=$L25)*('Cost baseline'!$C$5:$AB$5=O$4))/($L25-$K25+1)) -> 3 | P25: =IF($J25=0,0,$J25*SUMPRODUCT(('Cost baseline'!$C$4:$AB$4>=$K25)*('Cost baseline'!$C$4:$AB$4<=$L25)*('Cost baseline'!$C$5:$AB$5=P$4))/($L25-$K25+1)) -> 2.25 | Q25: =IF($J25=0,0,$J25*SUMPRODUCT(('Cost baseline'!$C$4:$AB$4>=$K25)*('Cost baseline'!$C$4:$AB$4<=$L25)*('Cost baseline'!$C$5:$AB$5=Q$4))/($L25-$K25+1)) -> 0 | R25: =IF($J25=0,0,$J25*SUMPRODUCT(('Cost baseline'!$C$4:$AB$4>=$K25)*('Cost baseline'!$C$4:$AB$4<=$L25)*('Cost baseline'!$C$5:$AB$5=R$4))/($L25-$K25+1)) -> 0
